# French translations for Open-Capture
# Copyright (C) 2019 ORGANIZATION
# This file is distributed under the same license as the project
# FIRST AUTHOR <nathan.cheval@edissyum.com>, 2021.
msgid ""
msgstr ""
"Project-Id-Version:  0.1\n"
"Report-Msgid-Bugs-To: nathan.cheval@edissyum.com\n"
"POT-Creation-Date: 2023-04-25 17:14+0200\n"
"PO-Revision-Date: 2019-09-02 17:48+0200\n"
"Last-Translator: Nathan CHEVAL <nathan.cheval@edissyum.com>\n"
"Language: fr\n"
"Language-Team: fr <nathan.cheval@edissyum.com>\n"
"Plural-Forms: nplurals=2; plural=(n > 1);\n"
"MIME-Version: 1.0\n"
"Content-Type: text/plain; charset=utf-8\n"
"Content-Transfer-Encoding: 8bit\n"
"Generated-By: Babel 2.12.1\n"

#: launch_worker.py:60 launch_worker.py:62 launch_worker_splitter.py:60
#: launch_worker_splitter.py:62
msgid "FILE_UPLOADED"
msgstr "Fichier téléversé via fs-watcher avec la chaîne entrante"

#: launch_worker.py:64 launch_worker_splitter.py:64
msgid "FILE_UPLOADED_WORKFLOW"
msgstr "Fichier téléversé via fs-watcher avec le workflow"

#: src/backend/verifier_exports.py:86 src/backend/verifier_exports.py:89
msgid "XML_DESTINATION_FOLDER_DOESNT_EXISTS"
msgstr "Le dossier de destination XML n'existe pas"

#: src/backend/verifier_exports.py:280 src/backend/verifier_exports.py:283
#: src/backend/verifier_exports.py:349 src/backend/verifier_exports.py:352
msgid "PDF_DESTINATION_FOLDER_DOESNT_EXISTS"
msgstr "Le dossier de destination PDF n'existe pas"

#: src/backend/controllers/splitter.py:452
#: src/backend/controllers/splitter.py:458 src/backend/verifier_exports.py:504
#: src/backend/verifier_exports.py:510 src/backend/verifier_exports.py:516
msgid "EXPORT_MEM_ERROR"
msgstr "Erreur lors de l'export vers MEM Courrier"

#: src/backend/verifier_exports.py:511
msgid "PDF_FILE_NOT_FOUND"
msgstr "Le fichier PDF est introuvable"

#: src/backend/verifier_exports.py:522
msgid "MEM_WS_INFO_WRONG"
msgstr "Les informations de connexion à MEM Courrier sont erronées"

#: src/backend/controllers/splitter.py:464 src/backend/verifier_exports.py:528
msgid "MEM_WS_INFO_EMPTY"
msgstr "Les informations de connexion à MEM Courrier sont vides"

#: src/backend/classes/MEMWebServices.py:39
msgid "HOST_NOT_FOUND"
msgstr "L'URL de l'hôte n'existe pas"

#: src/backend/classes/SMTP.py:223
msgid "RESET_PASSWORD"
msgstr "Réinitialiser le mot de passe"

#: src/backend/classes/SMTP.py:225
msgid "FORGOT_EMAIL_HEADER"
msgstr ""
"Bonjour,<br/><br/>Vous avez demandé à réinitialiser le mot de passe de "
"votre compte Open-Capture.<br/><br/>Pour modifier votre mot de passe, "
"veuillez cliquer sur le lien ci-dessous :<br/><br/>"

#: src/backend/classes/SMTP.py:225
msgid "CLICK_HERE"
msgstr "Cliquez ici"

#: src/backend/classes/SMTP.py:225
msgid "FORGOT_EMAIL_FOOTER"
msgstr ""
"<br/><br/>Si vous n'êtes pas à l'origine de cette demande, merci "
"d'ignorer cet e-mail."

#: src/backend/classes/SMTP.py:242
msgid "SMTP_TEST_SEND"
msgstr "Test d'envoi de mail"

#: src/backend/classes/SMTP.py:243
msgid "SMTP_TEST_SEND_BODY"
msgstr "Ceci est un test d'envoi de mail depuis l'application Open-Capture"

#: src/backend/controllers/accounts.py:63 src/backend/models/accounts.py:61
msgid "GET_SUPPLIER_BY_ID_ERROR"
msgstr "Erreur lors de la récupération du compte tier"

#: src/backend/controllers/accounts.py:76 src/backend/models/accounts.py:84
msgid "GET_ADDRESS_BY_ID_ERROR"
msgstr "Erreur lors de la récupération de l'adresse"

#: src/backend/controllers/accounts.py:103
#: src/backend/controllers/accounts.py:220
msgid "UPDATE_SUPPLIER_POSITIONS_ERROR"
msgstr "Erreur lors de la mise à jour des positions du compte tier"

#: src/backend/controllers/accounts.py:130
#: src/backend/controllers/accounts.py:251
msgid "UPDATE_SUPPLIER_PAGES_ERROR"
msgstr "Erreur lors de la mise à jour des pages du compte tier"

#: src/backend/controllers/accounts.py:183
#: src/backend/controllers/accounts.py:189
msgid "UPDATE_SUPPLIER_ERROR"
msgstr "Erreur lors de la mise à jour du tier"

#: src/backend/controllers/accounts.py:275
#: src/backend/controllers/accounts.py:281
#: src/backend/controllers/accounts.py:305
#: src/backend/controllers/accounts.py:311 src/backend/models/accounts.py:129
msgid "UPDATE_ADDRESS_ERROR"
msgstr "Erreur lors de la mise à jour de l'adresse"

#: src/backend/controllers/accounts.py:335 src/backend/models/accounts.py:149
msgid "CREATE_ADDRESS_ERROR"
msgstr "Erreur lors de la création de l'adresse"

#: src/backend/controllers/accounts.py:376
#: src/backend/controllers/accounts.py:382 src/backend/models/accounts.py:169
msgid "CREATE_SUPPLIER_ERROR"
msgstr "Erreur lors de la création du compte tier"

#: src/backend/controllers/accounts.py:383
msgid "SUPPLIER_VAT_NUMBER_ALREADY_EXISTS"
msgstr "Un compte tier existe déjà avec ce numéro de TVA"

#: src/backend/controllers/accounts.py:420 src/backend/controllers/user.py:219
#: src/backend/controllers/user.py:249 src/backend/models/accounts.py:233
#: src/backend/models/accounts.py:256 src/backend/models/accounts.py:275
#: src/backend/models/user.py:210
msgid "GET_CUSTOMER_BY_ID_ERROR"
msgstr "Erreur lors de la récupération du compte client"

#: src/backend/controllers/accounts.py:462
#: src/backend/controllers/accounts.py:468 src/backend/models/accounts.py:297
msgid "UPDATE_CUSTOMER_ERROR"
msgstr "Erreur lors de la mise à jour du compte client"

#: src/backend/controllers/accounts.py:497
#: src/backend/controllers/accounts.py:503 src/backend/models/accounts.py:317
msgid "CREATE_CUSTOMER_ERROR"
msgstr "Erreur lors de la création du compte client"

#: src/backend/controllers/accounts.py:504
msgid "CUSTOMER_VAT_NUMBER_ALREADY_EXISTS"
msgstr "Un compte client existe déjà avec ce numéro de TVA"

#: src/backend/controllers/accounts.py:518
#: src/backend/controllers/accounts.py:524 src/backend/models/accounts.py:339
msgid "DELETE_CUSTOMER_ERROR"
msgstr "Erreur lors de la suppression du compte client"

#: src/backend/controllers/accounts.py:539
#: src/backend/controllers/accounts.py:545 src/backend/models/accounts.py:191
msgid "DELETE_SUPPLIER_ERROR"
msgstr "Erreur lors de la suppression du compte tier"

#: src/backend/controllers/accounts.py:567
msgid "LOAD_SUPPLIER_REFERENCIAL_ERROR"
msgstr "Erreur lors du chargement du référentiel tier"

#: src/backend/controllers/artificial_intelligence.py:79
#: src/backend/controllers/artificial_intelligence.py:403
msgid "GET_IA_MODEL_BY_ID_ERROR"
msgstr "Erreur lors de la récupération du modèle d'apprentissage"

#: src/backend/controllers/artificial_intelligence.py:103
msgid "CREATE_IA_MODEL_ERROR"
msgstr "Erreur lors de la création du modèle d'apprentissage"

#: src/backend/controllers/artificial_intelligence.py:128
msgid "UPDATE_IA_MODEL_ERROR"
msgstr "Erreur lors de la mise à jour du modèle d'apprentissage"

#: src/backend/controllers/artificial_intelligence.py:404
#: src/backend/models/artificial_intelligence.py:59
msgid "IA_MODEL_DOESNT_EXISTS"
msgstr "Le modèle d'apprentissage n'existe pas"

#: src/backend/controllers/auth.py:66 src/backend/controllers/auth.py:222
#: src/backend/controllers/auth.py:266 src/backend/controllers/auth.py:276
#: src/backend/controllers/auth.py:286 src/backend/controllers/auth.py:289
#: src/backend/controllers/auth.py:300
msgid "JWT_ERROR"
msgstr "Erreur lors de l'authentification par token"

#: src/backend/controllers/auth.py:115
msgid "RESET_JWT_ERROR"
msgstr "Erreur lors de l'utilisation du token de réinitialisation"

#: src/backend/controllers/auth.py:148 src/backend/controllers/auth.py:163
#: src/backend/controllers/auth.py:201 src/backend/controllers/auth.py:246
#: src/backend/controllers/auth.py:319 src/backend/controllers/auth.py:330
#: src/backend/controllers/auth.py:340 src/backend/controllers/auth.py:367
#: src/backend/rest/auth.py:69
msgid "LOGIN_ERROR"
msgstr "Erreur lors de la connexion"

#: src/backend/controllers/auth.py:164
msgid "USER_WEBSERVICE"
msgstr ""
"L'utilisateur n'a pas le droit de se connecter à l'application "
"(utilisateur webservice)"

#: src/backend/controllers/auth.py:276
msgid "AUTHORIZATION_HEADER_INCORRECT"
msgstr "Le header d'authentification est incorrect ('Bearer' ou 'Basic' attendu)"

#: src/backend/controllers/auth.py:286
msgid "ACCOUNT_ALREADY_LOGGED"
msgstr ""
"Votre compte est déjà connecté sur un autre poste. Une seule connexion "
"est autorisée par utilisateur"

#: src/backend/controllers/auth.py:291 src/backend/controllers/auth.py:296
msgid "REST_ERROR"
msgstr "Erreur lors de l'authentification avec l'utilisateur webservice"

#: src/backend/controllers/auth.py:292
msgid "USER_DO_NOT_EXISTS"
msgstr "L'utilisateur n'existe pas en base de données"

#: src/backend/controllers/auth.py:296
msgid "PASSWORD_INCORRECT"
msgstr "Le mot de passe est incorrect"

#: src/backend/controllers/auth.py:300
msgid "VALID_TOKEN_MANDATORY"
msgstr "Un token valide est obligatoire"

#: src/backend/controllers/auth.py:331
msgid "SEVERAL_AUTH_METHODS_ENABLED"
msgstr "Plusieurs méthodes d'authentification sont activées"

#: src/backend/controllers/auth.py:355
msgid "LDAP_ERROR"
msgstr "Erreur LDAP"

#: src/backend/controllers/auth.py:356 src/backend/models/auth.py:140
msgid "NO_LDAP_CONFIGURATIONS_FOUND"
msgstr "Aucune configurations LDAP n'est disponible"

#: src/backend/controllers/auth.py:382
msgid "LOADING_METHODS_AUTH_ERROR"
msgstr "Echec lors de l'exécution de la requête"

#: src/backend/controllers/auth.py:394
msgid "DISABLE_LOGIN_METHOD_ERROR"
msgstr "Erreur lors de la désactivation de cette méthode"

#: src/backend/controllers/auth.py:406
msgid "ENABLE_LOGIN_METHOD_ERROR"
msgstr "Erreur lors de l'activation de cette méthode"

#: src/backend/controllers/auth.py:429 src/backend/controllers/auth.py:614
#: src/backend/controllers/auth.py:670 src/backend/controllers/auth.py:685
#: src/backend/controllers/auth.py:693 src/backend/controllers/auth.py:699
msgid "LDAP_CONNECTION_ERROR"
msgstr "Impossible de se connecter au serveur LDAP"

#: src/backend/controllers/auth.py:430
msgid "LOGIN_LDAP_ERROR"
msgstr "Information(s) de connexion incorrecte(s)"

#: src/backend/controllers/auth.py:602 src/backend/controllers/auth.py:608
msgid "LDAP_SYNCHRO_INFOS_ERROR"
msgstr "Information(s) de synchronisation incorrecte(s)"

#: src/backend/controllers/auth.py:604 src/backend/controllers/auth.py:610
#: src/backend/controllers/auth.py:616 src/backend/controllers/auth.py:622
#: src/backend/controllers/auth.py:628
msgid "LDAP_SYNCHRO_ERROR"
msgstr "Erreur lors de la synchronisation LDAP"

#: src/backend/controllers/auth.py:620 src/backend/controllers/auth.py:626
#: src/backend/controllers/auth.py:705 src/backend/rest/auth.py:122
msgid "INFOS_LDAP_NOT_COMPLETE"
msgstr "Informations non complètes"

#: src/backend/controllers/auth.py:668 src/backend/controllers/auth.py:683
#: src/backend/controllers/auth.py:691
msgid "BAD_CONNECTION_LDAP_INFOS"
msgstr "Information(s) incorrecte(s)"

#: src/backend/controllers/auth.py:703 src/backend/rest/auth.py:123
msgid "NOT_COMPLETE_CONNECTION_INFOS"
msgstr "Il manque une ou plusieurs informations pour établir la connexion"

#: src/backend/controllers/config.py:61
msgid "RETRIEVE_CONFIGURATION_ERRORS"
msgstr "Erreur lors de la récupération de la configuration"

#: src/backend/controllers/config.py:91
msgid "RETRIEVE_CONFIGURATIONS_ERRORS"
msgstr "Erreur lors de la récupération des configurations"

#: src/backend/controllers/config.py:121
msgid "RETRIEVE_DOCSERVERS_ERRORS"
msgstr "Erreur lors de la récupération des docservers"

#: src/backend/controllers/config.py:159
msgid "RETRIEVE_REGEX_ERRORS"
msgstr "Erreur lors de la récupération des regex"

#: src/backend/controllers/config.py:171 src/backend/controllers/config.py:191
#: src/backend/controllers/config.py:203 src/backend/controllers/config.py:223
#: src/backend/models/config.py:199 src/backend/models/config.py:223
msgid "UPDATE_CONFIGURATION_ERROR"
msgstr "Erreur lors de la mise à jour de la configuration"

#: src/backend/controllers/config.py:172 src/backend/controllers/config.py:204
msgid "JWT_EXPIRATION_COULDNT_BE_ZERO_OR_LESS"
msgstr "La valeur d'expiration du token ne peut être inférieure à 0"

#: src/backend/controllers/config.py:244 src/backend/models/config.py:245
msgid "UPDATE_REGEX_ERROR"
msgstr "Erreur lors de la mise à jour des REGEX"

#: src/backend/controllers/config.py:264 src/backend/models/config.py:271
msgid "UPDATE_DOCSERVER_ERROR"
msgstr "Erreur lors de la mise à jour de la docserver"

#: src/backend/controllers/config.py:306 src/backend/controllers/config.py:316
#: src/backend/controllers/config.py:321
msgid "ERROR_UPDATING_IMAGE"
msgstr "Erreur lors de la modification de l'image de connexion"

#: src/backend/controllers/config.py:307 src/backend/controllers/config.py:317
msgid "CUSTOM_IMAGE_PATH_NOT_WRITEABLE_OR_NOT_EXISTS"
msgstr "Le dossier d'image du custom n'est pas accessible"

#: src/backend/controllers/config.py:322
msgid "CUSTOM_NOT_PRESENT"
msgstr "Aucun custom n'est présent"

#: src/backend/controllers/custom_fields.py:33
#: src/backend/controllers/custom_fields.py:49
#: src/backend/controllers/custom_fields.py:62
msgid "CUSTOM_FIELDS_ERROR"
msgstr "Erreur sur les champs personnalisés"

#: src/backend/controllers/custom_fields.py:75
msgid "CUSTOM_FIELDS_DELETE_ERROR"
msgstr "Erreur lors de la suppression du champ personnalisé"

#: src/backend/controllers/doctypes.py:34
#: src/backend/controllers/doctypes.py:76 src/backend/models/doctypes.py:131
#: src/backend/models/doctypes.py:134
msgid "SET_DEFAULT_DOCTYPE_ERROR"
msgstr "Erreur lors de la modification du type de document par défaut"

#: src/backend/controllers/doctypes.py:40 src/backend/models/doctypes.py:51
msgid "ADD_DOCTYPE_ERROR"
msgstr "Erreur lors de l'ajout d'un type de document"

#: src/backend/controllers/doctypes.py:60
#: src/backend/controllers/doctypes.py:96
#: src/backend/controllers/doctypes.py:109
#: src/backend/controllers/doctypes.py:161
#: src/backend/controllers/doctypes.py:192
msgid "DOCTYPE_ERROR"
msgstr "Erreur sur les types de documents"

#: src/backend/controllers/doctypes.py:128
msgid "BUNDLESEPARATOR"
msgstr "SEPARATEUR DE LOT / BUNDLE SEPARATOR"

#: src/backend/controllers/doctypes.py:135
msgid "DOCUMENTSEPARATOR"
msgstr "SEPARATEUR DE DOCUMENT / DOCUMENT SEPARATOR"

#: src/backend/controllers/doctypes.py:154
msgid "DOCTYPESEPARATOR"
msgstr "SEPARATEUR AVEC TYPE DE DOCUMENT / SEPARATOR WITH DOCUMENT TYPE"

#: src/backend/controllers/forms.py:71 src/backend/controllers/forms.py:97
#: src/backend/controllers/forms.py:214
msgid "FORMS_ERROR"
msgstr "Erreur sur les formulaires"

#: src/backend/controllers/forms.py:112 src/backend/controllers/forms.py:161
#: src/backend/models/forms.py:66
msgid "GET_FORM_BY_ID_ERROR"
msgstr "Erreur lors de la récupération du formulaire"

#: src/backend/controllers/forms.py:144
msgid "GET_FORM_FIELDS_BY_FORM_ID_ERROR"
msgstr "Erreur lors de la récupération des champs du formulaire"

#: src/backend/controllers/forms.py:208 src/backend/controllers/forms.py:337
#: src/backend/controllers/forms.py:343
msgid "UPDATE_FORMS_FIELDS_ERROR"
msgstr "Erreur lors de la mise à jour des champs du formulaire"

#: src/backend/controllers/forms.py:228 src/backend/controllers/forms.py:234
msgid "DELETE_FORM_ERROR"
msgstr "Erreur lors de la suppression du formulaire"

#: src/backend/controllers/forms.py:243 src/backend/controllers/inputs.py:107
#: src/backend/controllers/outputs.py:65
#: src/backend/controllers/positions_masks.py:144
#: src/backend/controllers/workflow.py:100
msgid "COPY_OF"
msgstr "Copie de"

#: src/backend/controllers/forms.py:261 src/backend/controllers/forms.py:267
msgid "DUPLICATE_FORM_ERROR"
msgstr "Erreur lors de la duplication du formulaire"

#: src/backend/controllers/forms.py:281 src/backend/controllers/forms.py:287
msgid "DISABLE_FORM_ERROR"
msgstr "Erreur lors de la désactivation du formulaire"

#: src/backend/controllers/forms.py:301 src/backend/controllers/forms.py:307
msgid "ENABLE_FORM_ERROR"
msgstr "Erreur lors de l'activation du formulaire"

#: src/backend/controllers/forms.py:323
msgid "GET_FORMS_FIELDS_ERROR"
msgstr "Erreur lors de la récupération des champs du formulaire"

#: src/backend/controllers/history.py:31
msgid "ADD_HISTORY_ERROR"
msgstr "Erreur lors de l'ajout dans l'historique"

#: src/backend/controllers/inputs.py:75 src/backend/controllers/inputs.py:135
#: src/backend/controllers/inputs.py:162 src/backend/controllers/inputs.py:173
#: src/backend/controllers/inputs.py:186
msgid "CREATE_INPUT_ERROR"
msgstr "Erreur lors de la création de la chaîne entrante"

#: src/backend/controllers/inputs.py:76 src/backend/controllers/inputs.py:136
#: src/backend/controllers/workflow.py:144
#: src/backend/controllers/workflow.py:194
msgid "NOT_ALLOWED_INPUT_PATH"
msgstr "Le chemin de capture de la chaîne entrante n'est pas autorisé"

#: src/backend/controllers/inputs.py:89 src/backend/controllers/inputs.py:95
msgid "UPDATE_INPUT_ERROR"
msgstr "Erreur lors de la mise à jour de la chaîne entrante"

#: src/backend/controllers/inputs.py:120 src/backend/controllers/inputs.py:126
msgid "DUPLICATE_INPUT_ERROR"
msgstr "Erreur lors de la duplication de la chaîne entrante"

#: src/backend/controllers/inputs.py:163
msgid "INPUT_ID_ALREADY_EXISTS"
msgstr "Le libellé technique de la chaîne entrante existe déjà"

#: src/backend/controllers/inputs.py:174
#: src/backend/controllers/workflow.py:167
msgid "INPUT_FOLDER_ALREADY_EXISTS"
msgstr "Le chemin de capture est déjà paramétré dans une autre chaîne entrante"

#: src/backend/controllers/inputs.py:199
msgid "GET_INPUT_BY_ID_ERROR"
msgstr "Erreur lors de récupération de la chaîne entrante"

#: src/backend/controllers/inputs.py:212
msgid "GET_INPUT_BY_INPUT_ID_ERROR"
msgstr "Erreur lors de la récupération de la chaîne entrante"

#: src/backend/controllers/inputs.py:233 src/backend/controllers/inputs.py:239
msgid "DELETE_INPUT_ERROR"
msgstr "Erreur lors de le suppression de la chaîne entrante"

#: src/backend/controllers/inputs.py:275
msgid "FS_WATCHER_DELETION_ERROR"
msgstr "Erreur lors de la suppression des paramètres du fs watcher"

#: src/backend/controllers/inputs.py:276 src/backend/controllers/inputs.py:343
#: src/backend/controllers/workflow.py:308
msgid "FS_WATCHER_CONFIG_DOESNT_EXIST"
msgstr "La configuration du fs watcher est introuvable"

#: src/backend/controllers/inputs.py:322 src/backend/controllers/inputs.py:342
#: src/backend/controllers/workflow.py:285
#: src/backend/controllers/workflow.py:307
msgid "FS_WATCHER_CREATION_ERROR"
msgstr "Erreur lors de la création des paramètres du fs watcher"

#: src/backend/controllers/inputs.py:323 src/backend/controllers/workflow.py:54
#: src/backend/controllers/workflow.py:286
msgid "CAN_NOT_CREATE_FOLDER_PERMISSION_ERROR"
msgstr "Problème de permissions pour créer le dossier"

#: src/backend/controllers/inputs.py:348
#: src/backend/controllers/workflow.py:313
msgid "SCRIPT_SAMPLE_DOESNT_EXISTS"
msgstr "Le script d'exemple n'existe pas"

#: src/backend/controllers/inputs.py:354
#: src/backend/controllers/workflow.py:319
msgid "SCRIPT_FOLDER_DOESNT_EXISTS"
msgstr "Le dossier des scripts n'existe pas"

#: src/backend/controllers/mailcollect.py:36
msgid "RETRIEVE_PROCESSES_ERROR"
msgstr "Erreur lors de la récupération des processus MailCollect"

#: src/backend/controllers/mailcollect.py:52
msgid "UPDATE_PROCESS_ERROR"
msgstr "Erreur lors de la mise à jour du processus MailCollect"

#: src/backend/controllers/mailcollect.py:68
msgid "CREATE_PROCESS_ERROR"
msgstr "Erreur lors de la création d'un processus MailCollect"

#: src/backend/controllers/mailcollect.py:82
#: src/backend/controllers/mailcollect.py:88
msgid "DELETE_MAILCOLLECT_PROCESS_ERROR"
msgstr "Erreur lors de la suppression d'un processus MailCollect"

#: src/backend/controllers/mailcollect.py:102
#: src/backend/controllers/mailcollect.py:108
msgid "ENABLE_MAILCOLLECT_PROCESS_ERROR"
msgstr "Erreur lors de l'activation d'un processus MailCollect"

#: src/backend/controllers/mailcollect.py:122
#: src/backend/controllers/mailcollect.py:128
msgid "DISABLE_MAILCOLLECT_PROCESS_ERROR"
msgstr "Erreur lors de la désactivation d'un processus MailCollect"

#: src/backend/controllers/mailcollect.py:142
#: src/backend/controllers/mailcollect.py:152
msgid "MAILCOLLECT_ERROR"
msgstr "Erreur MailCollect"

#: src/backend/controllers/outputs.py:72 src/backend/controllers/outputs.py:78
msgid "DUPLICATE_OUTPUT_ERROR"
msgstr "Erreur lors de la duplication de la chaîne sortante"

#: src/backend/controllers/outputs.py:107
#: src/backend/controllers/outputs.py:129
#: src/backend/controllers/outputs.py:135
msgid "UPDATE_OUTPUT_ERROR"
msgstr "Erreur lors de mise à jour de la chaîne sortante"

#: src/backend/controllers/outputs.py:108
msgid "NOT_ALLOWED_OUTPUT_PATH"
msgstr "Le chemin d'export de la chaîne sortant n'est pas autorisé"

#: src/backend/controllers/outputs.py:159
msgid "CREATE_OUTPUT_ERROR"
msgstr "Erreur lors de la création de la chaîne sortante"

#: src/backend/controllers/outputs.py:172
msgid "GET_OUTPUT_BY_ID_ERROR"
msgstr "Erreur lors de la récupération de la chaîne sortante"

#: src/backend/controllers/outputs.py:185
msgid "GET_OUTPUT_TYPE_BY_ID_ERROR"
msgstr "Erreur lors de la récupération des types de chaîne sortante"

#: src/backend/controllers/outputs.py:199
#: src/backend/controllers/outputs.py:205
msgid "DELETE_OUTPUT_ERROR"
msgstr "Erreur lors de la suppression de la chaîne sortante"

#: src/backend/controllers/positions_masks.py:43
#: src/backend/controllers/positions_masks.py:67
#: src/backend/controllers/positions_masks.py:109
#: src/backend/controllers/positions_masks.py:115
msgid "POSITION_MASKS_ERROR"
msgstr "Erreur sur les masques de positionnement"

#: src/backend/controllers/positions_masks.py:82
msgid "GET_POSITION_MASK_BY_ID_ERROR"
msgstr "Erreur lors de la récupération du masque de positionnement"

#: src/backend/controllers/positions_masks.py:129
#: src/backend/controllers/positions_masks.py:135
msgid "DELETE_POSITION_MASK_ERROR"
msgstr "Erreur lors de la suppression du masque de positionnement"

#: src/backend/controllers/positions_masks.py:160
#: src/backend/controllers/positions_masks.py:166
msgid "DUPLICATE_POSITIONS_MASKS_ERROR"
msgstr "Erreur lors de la duplication du masque de positionnement"

#: src/backend/controllers/positions_masks.py:180
#: src/backend/controllers/positions_masks.py:186
msgid "DISABLE_POSITION_MASK_ERROR"
msgstr "Erreur lors de désactivation du masque de positionnement"

#: src/backend/controllers/positions_masks.py:200
#: src/backend/controllers/positions_masks.py:206
msgid "ENABLE_POSITION_MASK_ERROR"
msgstr "Erreur lors de l'activation du masque de positionnement"

#: src/backend/controllers/positions_masks.py:229
msgid "UPDATE_POSITIONS_BY_POSITIONS_MASK_ID_ERROR"
msgstr "Erreur lors de la mise à jour des positions du masque de positionnement"

#: src/backend/controllers/positions_masks.py:252
msgid "UPDATE_PAGES_BY_POSITIONS_MASK_ID_ERROR"
msgstr "Erreur lors de la mise à jour des pages du masque de positionnement"

#: src/backend/controllers/positions_masks.py:270
msgid "DELETE_POSITIONS_BY_POSITION_MASK_ID_ERROR"
msgstr "Erreur lors de la suppression des positions du masque de positionnement"

#: src/backend/controllers/positions_masks.py:288
msgid "DELETE_PAGES_BY_POSITION_MASK_ID_ERROR"
msgstr "Erreur lors de la suppression des pages du masque de positionnement"

#: src/backend/controllers/privileges.py:38
#: src/backend/controllers/privileges.py:66
#: src/backend/controllers/privileges.py:94
msgid "GET_PRIVILEGES_ERROR"
msgstr "Erreur lors de la récupération des privilèges"

#: src/backend/controllers/roles.py:56 src/backend/controllers/roles.py:62
#: src/backend/controllers/roles.py:104 src/backend/controllers/roles.py:110
#: src/backend/models/roles.py:84
msgid "UPDATE_ROLE_ERROR"
msgstr "Erreur lors de la mise à jour du rôle"

#: src/backend/controllers/roles.py:84 src/backend/models/roles.py:104
msgid "CREATE_ROLE_ERROR"
msgstr "Erreur lors de la création du rôle"

#: src/backend/controllers/roles.py:123
msgid "GET_ROLE_BY_ID_ERROR"
msgstr "Erreur lors de la récupération du rôle"

#: src/backend/controllers/roles.py:137 src/backend/controllers/roles.py:143
msgid "DELETE_ROLE_ERROR"
msgstr "Erreur lors de la suppression du rôle"

#: src/backend/controllers/roles.py:157 src/backend/controllers/roles.py:163
msgid "DISABLE_ROLE_ERROR"
msgstr "Erreur lors de la désactivation du rôle"

#: src/backend/controllers/roles.py:177 src/backend/controllers/roles.py:183
msgid "ENABLE_ROLE_ERROR"
msgstr "Erreur lors de l'activation du rôle"

#: src/backend/controllers/smtp.py:49
msgid "SMTP_TEST_SEND_EMAIL_ERROR"
msgstr "Erreur lors de l'envoi du mail de test"

#: src/backend/controllers/smtp.py:55
msgid "SMTP_TEST_CONNECTION_ERROR"
msgstr "Erreur lors de la connexion SMTP"

#: src/backend/controllers/splitter.py:103
msgid "LOAD_METADATA_ERROR"
msgstr "Erreur du chargement des métadonnées"

#: src/backend/controllers/splitter.py:159
#: src/backend/controllers/verifier.py:104
msgid "AT"
msgstr "à"

#: src/backend/controllers/splitter.py:183
msgid "FORM_UNDEFINED"
msgstr "Formulaire non défini"

#: src/backend/controllers/splitter.py:186
msgid "CUSTOMER_UNDEFINED"
msgstr "Compte client non défini"

#: src/backend/controllers/splitter.py:246
msgid "BATCH_NOT_FOUND"
msgstr "Lot non trouvé"

#: src/backend/controllers/splitter.py:247
msgid "BATCH_ID_NOT_FOUND"
msgstr "Lot  %(id)s non trouvé"

#: src/backend/controllers/splitter.py:256
#: src/backend/controllers/verifier.py:643
msgid "UPDATE_STATUS_ERROR"
msgstr "Erreur lors de la mise à jour du statut"

#: src/backend/controllers/splitter.py:291
#: src/backend/controllers/verifier.py:377
msgid "REMOVE_LOCK_BY_USER_ID_ERROR"
msgstr "Erreur lors de la suppression du verrou"

#: src/backend/controllers/splitter.py:401
msgid "ADD_DOCUMENT_ERROR"
msgstr "Erreur lors de l'ajout d'un document"

#: src/backend/controllers/splitter.py:536
#: src/backend/controllers/splitter.py:805
msgid "EXPORT_PDF_ERROR"
msgstr "Erreur lors de l'export PDF"

#: src/backend/controllers/splitter.py:558
#: src/backend/controllers/splitter.py:830
msgid "EXPORT_XML_ERROR"
msgstr "Erreur lors de l'export XML"

#: src/backend/controllers/splitter.py:581
msgid "UPDATE_BATCH_ERROR"
msgstr "Erreur lors de la mise à jour du lot"

#: src/backend/controllers/splitter.py:594
msgid "UPDATE_DOCUMENTS_ERROR"
msgstr "Erreur lors de la mise à jour du document"

#: src/backend/controllers/splitter.py:607
msgid "UPDATE_DOCUMENT_ERROR"
msgstr "Erreur lors de la mise à jour du document"

#: src/backend/controllers/splitter.py:622
#: src/backend/controllers/splitter.py:643
#: src/backend/controllers/splitter.py:658
#: src/backend/controllers/splitter.py:673
msgid "UPDATE_PAGES_ERROR"
msgstr "Erreur lors de la modification des pages"

#: src/backend/controllers/splitter.py:687
msgid "CMIS_CONNECTION_ERROR"
msgstr "Erreur lors de la connexion CMIS"

#: src/backend/controllers/splitter.py:700
msgid "OPENADS_CONNECTION_ERROR"
msgstr "Erreur lors de la connexion OpenADS"

#: src/backend/controllers/splitter.py:880
msgid "CHECK_FOLDER_ERROR"
msgstr "Erreur lors de la vérification du dossier"

#: src/backend/controllers/splitter.py:881
msgid "FOLDER_DOES_NOT_EXIST"
msgstr "Dossier inexistant"

#: src/backend/controllers/splitter.py:898
msgid "OPENADS_ADD_DOC_ERROR"
msgstr "Erreur lors de l'envoi de document à OpenADS"

#: src/backend/controllers/splitter.py:992
#: src/backend/controllers/verifier.py:622 src/backend/models/splitter.py:572
#: src/backend/models/verifier.py:171
msgid "GET_TOTALS_ERROR"
msgstr "Erreur lors de la récupération des totaux"

#: src/backend/controllers/status.py:31
msgid "RETRIEVES_STATUS_ERROR"
msgstr "Erreur lors de la récupération des status"

#: src/backend/controllers/tasks_watcher.py:34
msgid "CREATE_TASK_ERROR"
msgstr "Erreur lors de la création d'une nouvelle tâche"

#: src/backend/controllers/user.py:64
msgid "CREATE_USER_ERROR"
msgstr "Erreur lors de la création de l'utilisateur"

#: src/backend/controllers/user.py:108 src/backend/controllers/user.py:124
#: src/backend/controllers/user.py:190 src/backend/models/user.py:140
#: src/backend/models/user.py:187
msgid "GET_USER_BY_ID_ERROR"
msgstr "Erreur lors de la récupération de l'utilisateur"

#: src/backend/controllers/user.py:141
msgid "GET_USER_BY_USERNAME_ERROR"
msgstr "Erreur lors de la récupération de l'utilisateur"

#: src/backend/controllers/user.py:164
msgid "SEND_EMAIL_FORGOT_PASSWORD_ERROR"
msgstr "Erreur lors de l'envoi de l'email de réinitialisation du mot de passe"

#: src/backend/controllers/user.py:184 src/backend/controllers/user.py:189
msgid "RESET_PASSWORD_ERROR"
msgstr "Erreur lors de la réinitilisation du mot de passe"

#: src/backend/controllers/user.py:185
msgid "RESET_TOKEN_MISMATCH"
msgstr "Le token de réinitialisation est invalide. Il est peut être expiré"

#: src/backend/controllers/user.py:270
msgid "UPDATE_PROFILE"
msgstr "Mise à jour du profile"

#: src/backend/controllers/user.py:271
msgid "ERROR_OLD_PASSWORD_NOT_MATCH"
msgstr "L'ancien mot de passe ne corresponds pas"

#: src/backend/controllers/user.py:277
msgid "UPDATE_USER"
msgstr "Mise à jour de l'utilisateur"

#: src/backend/controllers/user.py:278
msgid "ERROR_PASSWORD_NOT_MATCH"
msgstr "Les mots de passes ne correspondent pas"

#: src/backend/controllers/user.py:306 src/backend/controllers/user.py:312
#: src/backend/models/user.py:255 src/backend/models/user.py:321
msgid "UPDATE_USER_ERROR"
msgstr "Erreur lors de la mise à jour de l'utilisateur"

#: src/backend/controllers/user.py:326 src/backend/controllers/user.py:332
msgid "DELETE_USER_ERROR"
msgstr "Erreur lors de la suppression de l'utilisateur"

#: src/backend/controllers/user.py:346 src/backend/controllers/user.py:352
msgid "DISABLE_USER_ERROR"
msgstr "Erreur lors de désactiver de l'utilisateur"

#: src/backend/controllers/user.py:366 src/backend/controllers/user.py:372
msgid "ENABLE_USER_ERROR"
msgstr "Erreur lors de l'activation de l'utilisateur"

#: src/backend/controllers/user.py:389 src/backend/controllers/user.py:395
#: src/backend/models/user.py:277
msgid "UPDATE_CUSTOMERS_USER_ERROR"
msgstr "Erreur lors de la mise à jour des comptes clients de l'utilisateur"

#: src/backend/controllers/user.py:410 src/backend/controllers/user.py:417
#: src/backend/models/user.py:299
msgid "UPDATE_FORMS_USER_ERROR"
msgstr "Erreur lors de la mise à jour des formulaires de l'utilisateur"

#: src/backend/controllers/verifier.py:85 src/backend/models/splitter.py:219
#: src/backend/models/verifier.py:40
msgid "GET_INVOICE_BY_ID_ERROR"
msgstr "Erreur lors de la récupération de la facture"

#: src/backend/controllers/verifier.py:199
#: src/backend/controllers/verifier.py:301
msgid "UPDATE_INVOICE_POSITIONS_ERROR"
msgstr "Erreur lors de la mise à jour des positions de la facture"

#: src/backend/controllers/verifier.py:222
#: src/backend/controllers/verifier.py:319
msgid "UPDATE_INVOICE_PAGES_ERROR"
msgstr "Erreur lors de la mise à jour des pages de la facture"

#: src/backend/controllers/verifier.py:245
#: src/backend/controllers/verifier.py:263
msgid "UPDATE_INVOICE_DATA_ERROR"
msgstr "Erreur lors de la mise à jour des données de la facture"

#: src/backend/controllers/verifier.py:333
#: src/backend/controllers/verifier.py:339
msgid "DELETE_INVOICE_ERROR"
msgstr "Erreur lors de la suppression de la facture"

#: src/backend/controllers/verifier.py:354
#: src/backend/controllers/verifier.py:360
msgid "UPDATE_INVOICE_ERROR"
msgstr "Erreur lors de la mise à jour de la facture"

#: src/backend/controllers/verifier.py:522
#: src/backend/controllers/verifier.py:525
#: src/backend/controllers/verifier.py:542
#: src/backend/controllers/verifier.py:565
#: src/backend/controllers/verifier.py:566
msgid "API_INSEE_ERROR_CONNEXION"
msgstr "Erreur lors de la connexion à l'api de l'INSEE"

#: src/backend/controllers/verifier.py:594
msgid "VAT_NOT_VALID"
msgstr "Numéro de TVA invalide"

#: src/backend/controllers/verifier.py:599
#: src/backend/controllers/verifier.py:600
msgid "VAT_API_ERROR"
msgstr "Impossible de joindre l'API de vérification du numéro de TVA"

#: src/backend/controllers/verifier.py:633
msgid "INVOICE_NOT_FOUND"
msgstr "Facture non trouvée"

#: src/backend/controllers/verifier.py:634
msgid "INVOICE_ID_NOT_FOUND"
msgstr "Facture  %(id)s non trouvée"

#: src/backend/controllers/workflow.py:53
#: src/backend/controllers/workflow.py:60
msgid "WORKFLOW_FOLDER_CREATION_ERROR"
msgstr "Erreur lors de la création du dossier de travail"

#: src/backend/controllers/workflow.py:61
msgid "CAN_NOT_ACCESS_FOLDER_PERMISSION_ERROR"
msgstr "Impossible d'accéder au dossier de travail"

#: src/backend/controllers/workflow.py:75
msgid "GET_WORKFLOW_BY_ID_ERROR"
msgstr "Erreur lors de la récupération du workflow"

#: src/backend/controllers/workflow.py:88
msgid "GET_WORKFLOW_BY_WORKFLOW_ID_ERROR"
msgstr "Erreur lors de la récupération du workflow"

#: src/backend/controllers/workflow.py:112
#: src/backend/controllers/workflow.py:118
msgid "DUPLICATE_WORKFLOW_ERROR"
msgstr "Erreur lors de la duplication du workflow"

#: src/backend/controllers/workflow.py:143
#: src/backend/controllers/workflow.py:155
#: src/backend/controllers/workflow.py:166
#: src/backend/controllers/workflow.py:184
msgid "CREATE_WORKFLOW_ERROR"
msgstr "Erreur lors de la création du workflow"

#: src/backend/controllers/workflow.py:156
msgid "WORKFLOW_ID_ALREADY_EXISTS"
msgstr "Le libellé technique du workflow existe déjà"

#: src/backend/controllers/workflow.py:193
#: src/backend/controllers/workflow.py:211
#: src/backend/controllers/workflow.py:217
msgid "UPDATE_WORKFLOW_ERROR"
msgstr "Erreur lors de la mise à jour du workflow"

#: src/backend/controllers/workflow.py:232
#: src/backend/controllers/workflow.py:238
msgid "DELETE_WORKFLOW_ERROR"
msgstr "Erreur lors de la suppression du workflow"

#: src/backend/models/accounts.py:107
msgid "SUPPLIER_UPDATE_ERROR"
msgstr "Erreur lors de la mise à jour du tier"

#: src/backend/models/artificial_intelligence.py:80
msgid "IA_MODEL_CREATE_ERROR"
msgstr "Erreur lors de la création du modèle d'apprentissage"

#: src/backend/models/artificial_intelligence.py:101
msgid "IA_MODEL_UPDATE_ERROR"
msgstr "Erreur lors de la modification du modèle d'apprentissage"

#: src/backend/models/auth.py:43 src/backend/models/auth.py:101
#: src/backend/models/user.py:43 src/backend/rest/auth.py:70
msgid "BAD_USERNAME"
msgstr "Mauvais nom de compte"

#: src/backend/models/auth.py:45 src/backend/models/user.py:45
msgid "BAD_PASSWORD"
msgstr "Mauvais mot de passe"

#: src/backend/models/auth.py:47
msgid "USER_DELETED"
msgstr "Utilisateur supprimé"

#: src/backend/models/auth.py:49
msgid "USER_DISABLED"
msgstr "Utilisateur desactivé"

#: src/backend/models/auth.py:70 src/backend/models/auth.py:80
#: src/backend/models/roles.py:60
msgid "ROLE_DOESNT_EXISTS"
msgstr "Le rôle n'existe pas"

#: src/backend/models/auth.py:165
msgid "UPDATE_LOGIN_METHOD_ERROR"
msgstr "Erreur lors de la mise à jour de la méthode d'authentification"

#: src/backend/models/auth.py:211
msgid "DISABLE_LOGIN_METHOD_DATA_ERROR"
msgstr "Erreur lors de la désactivation de cette méthode d'authentification"

#: src/backend/models/auth.py:233
msgid "ENABLE_LOGIN_METHOD_DATA_ERROR"
msgstr "Erreur lors de l'activation de cette méthode d'authentification"

#: src/backend/models/custom_fields.py:55
msgid "ADD_CUSTOM_FIELD_ERROR"
msgstr "Erreur lors de la création du champ custom"

#: src/backend/models/custom_fields.py:58
msgid "CUSTOM_FIELD_ALREADY_EXIST"
msgstr "Le champ custom existe déjà"

#: src/backend/models/custom_fields.py:106
msgid "UPDATE_CUSTOM_FIELDS_ERROR"
msgstr "Erreur lors de la mise à jour du champ custom"

#: src/backend/models/custom_fields.py:129
msgid "DELETE_CUSTOM_FIELDS_ERROR"
msgstr "Erreur lors de la suppression du champ custom"

#: src/backend/models/doctypes.py:54
msgid "DOCTYPE_ALREADY_EXIST"
msgstr "Le type de document existe déjà"

#: src/backend/models/doctypes.py:100
msgid "UPDATE_DOCTYPE_ERROR"
msgstr "Erreur lors de la mise à jour du type de document"

#: src/backend/models/forms.py:45
msgid "GET_FORMS_ERROR"
msgstr "Erreur lors de la récupération des formulaires"

#: src/backend/models/forms.py:89
msgid "GET_FORM_SETTINGS_BY_ID_ERROR"
msgstr "Erreur lors de la récupération des paramètres du formulaire"

#: src/backend/models/forms.py:112
msgid "GET_DEFAULT_FORM_ERROR"
msgstr "Erreur lors de la récupération du formulaire par défaut"

#: src/backend/models/forms.py:136
msgid "UPDATE_FORM_ERROR"
msgstr "Erreur lors de la mise à jour du formulaire"

#: src/backend/models/forms.py:158
msgid "UPDATE_FORM_FIELDS_ERROR"
msgstr "Erreur lors de la mise à jour des champs du formulaire"

#: src/backend/models/forms.py:215
msgid "ADD_FORM_ERROR"
msgstr "Erreur lors de la création du formulaire"

#: src/backend/models/forms.py:218
msgid "FORM_LABEL_ALREADY_EXIST"
msgstr "Le libellé de formulaire existe déjà"

#: src/backend/models/inputs.py:60 src/backend/models/inputs.py:83
msgid "INPUT_DOESNT_EXISTS"
msgstr "La chaîne entrante n'existe pas"

#: src/backend/models/inputs.py:125
msgid "INPUT_UPDATE_ERROR"
msgstr "Erreur lors de la mise à jour de la chaîne entrante"

#: src/backend/models/inputs.py:145
msgid "INPUT_CREATE_ERROR"
msgstr "Erreur lors de la création de la chaîne entrante"

#: src/backend/models/mailcollect.py:85
msgid "MAILCOLLECT_PROCESS_UPDATE_ERROR"
msgstr "Erreur lors de la mise à jour d'un processus MailCollect"

#: src/backend/models/outputs.py:78
msgid "OUTPUT_DOESNT_EXISTS"
msgstr "La chaîne sortante n'existe pas"

#: src/backend/models/outputs.py:101
msgid "OUTPUT_TYPE_DOESNT_EXISTS"
msgstr "Le type de chaîne sortante n'existe aps"

#: src/backend/models/outputs.py:125
msgid "OUTPUT_UPDATE_ERROR"
msgstr "Erreur lors de la mise à jour de la chaîne sortante"

#: src/backend/models/outputs.py:145
msgid "OUTPUT_CREATE_ERROR"
msgstr "Erreur lors de la création de la chaîne sortante"

#: src/backend/models/positions_masks.py:63
msgid "GET_POSITIONS_MASKS_BY_ID_ERROR"
msgstr "Erreur lors de la récupération du masque de positionnement"

#: src/backend/models/positions_masks.py:87
msgid "UPDATE_POSITIONS_MASKS_ERROR"
msgstr "Erreur lors de la mise à jour du masque de positionnement"

#: src/backend/models/positions_masks.py:109
msgid "UPDATE_POSITIONS_MASKS_FIELDS_ERROR"
msgstr "Erreur lors de la mise à jour des champs du masque de positionnement"

#: src/backend/models/positions_masks.py:144
msgid "ADD_POSITIONS_MASKS_ERROR"
msgstr "Erreur lors de la création du masque de positionnement"

#: src/backend/models/positions_masks.py:147
msgid "POSITIONS_MASK_LABEL_ALREADY_EXIST"
msgstr "Le libellé du masque de positionnement existe déjà"

#: src/backend/models/privileges.py:38 src/backend/models/privileges.py:59
#: src/backend/models/privileges.py:83
msgid "ERROR_RETRIEVING_PRIVILEGES"
msgstr "Erreur lors de la récupération des privilèges"

#: src/backend/models/roles.py:126
msgid "ROLE_PRIVILEGES_UPDATE_ERROR"
msgstr "Erreur lors de la mise à jour des privilèges du rôle"

#: src/backend/models/roles.py:148
msgid "ROLE_PRIVILEGES_CREATE_ERROR"
msgstr "Erreur lors de la création des privilèges du rôle"

#: src/backend/models/splitter.py:78
msgid "GET_MAX_SPLIT_INDEX_ERROR"
msgstr "Erreur lors de l'obtention de l'index du Splitter"

#: src/backend/models/splitter.py:125
msgid "UPDATE_SETTINGS_ERROR"
msgstr "Erreur lors de la mise à jour des paramètres du Splitter"

#: src/backend/models/splitter.py:150
msgid "INSERT_PAGE_ERROR"
msgstr "Erreur lors de l'insertion des pages du Splitter"

#: src/backend/models/splitter.py:244
msgid "GET_DOCUMENTS_ERROR"
msgstr "Erreur lors de la récupération des documents du Splitter"

#: src/backend/models/splitter.py:266 src/backend/models/splitter.py:289
msgid "GET_PAGES_ERROR"
msgstr "Erreur lors de l'obtention des pages du Splitter"

#: src/backend/models/splitter.py:311
msgid "GET_MAX_SOURCE_PAGE_VALUE_ERROR"
msgstr "Erreur lors de l'obtention de la valeur des pages source du Splitter"

#: src/backend/models/splitter.py:334
msgid "GET_DOCUMENT_ERROR"
msgstr "Erreur lors de la récupération du document"

#: src/backend/models/splitter.py:356
msgid "GET_DOCUMENT_MAX_SPLIT_INDEX_ERROR"
msgstr "Erreur lors de l'obtention de l'index maximum du Splitter"

#: src/backend/models/status.py:40
msgid "NO_STATUS"
msgstr "Aucun status existant"

#: src/backend/models/tasks_watcher.py:89
msgid "UPDATE_TASK_ERROR"
msgstr "Erreur lors de la mise à jour d'une tâche"

#: src/backend/models/user.py:47
msgid "USER"
msgstr "L'utilisateur"

#: src/backend/models/user.py:47
msgid "ALREADY_REGISTERED"
msgstr "est déjà enregistré"

#: src/backend/models/user.py:163
msgid "GET_USER_BY_MAIL_ERROR"
msgstr "Aucun utilisateur asssocié à cette addresse email"

#: src/backend/models/user.py:232
msgid "GET_FORMS_BY_USER_ID_ERROR"
msgstr "Erreur lors de la récupération des formulaires de l'utilisateur"

#: src/backend/models/verifier.py:104 src/backend/models/verifier.py:125
msgid "INVOICE_UPDATE_ERROR"
msgstr "Erreur lors de la mise à jour de la facture"

#: src/backend/models/workflow.py:60 src/backend/models/workflow.py:83
msgid "WORKFLOW_DOESNT_EXISTS"
msgstr "Le workflow n'existe pas"

#: src/backend/models/workflow.py:105
msgid "WORKFLOW_CREATE_ERROR"
msgstr "Erreur lors de la création du modèle workflow"

#: src/backend/models/workflow.py:127
msgid "WORKFLOW_UPDATE_ERROR"
msgstr "Erreur lors de la modification du workflow"

#: src/backend/rest/accounts.py:34 src/backend/rest/accounts.py:44
#: src/backend/rest/accounts.py:56 src/backend/rest/accounts.py:67
#: src/backend/rest/accounts.py:79 src/backend/rest/accounts.py:91
#: src/backend/rest/accounts.py:104 src/backend/rest/accounts.py:116
#: src/backend/rest/accounts.py:129 src/backend/rest/accounts.py:147
#: src/backend/rest/accounts.py:158 src/backend/rest/accounts.py:169
#: src/backend/rest/accounts.py:180 src/backend/rest/accounts.py:200
#: src/backend/rest/accounts.py:220 src/backend/rest/accounts.py:232
#: src/backend/rest/accounts.py:242 src/backend/rest/accounts.py:253
#: src/backend/rest/accounts.py:265 src/backend/rest/accounts.py:276
#: src/backend/rest/accounts.py:320
#: src/backend/rest/artificial_intelligence.py:30
#: src/backend/rest/artificial_intelligence.py:40
#: src/backend/rest/artificial_intelligence.py:51
#: src/backend/rest/artificial_intelligence.py:61
#: src/backend/rest/artificial_intelligence.py:71
#: src/backend/rest/artificial_intelligence.py:83
#: src/backend/rest/artificial_intelligence.py:96
#: src/backend/rest/artificial_intelligence.py:108 src/backend/rest/auth.py:103
#: src/backend/rest/auth.py:113 src/backend/rest/auth.py:133
#: src/backend/rest/auth.py:144 src/backend/rest/auth.py:167
#: src/backend/rest/auth.py:178 src/backend/rest/config.py:31
#: src/backend/rest/config.py:46 src/backend/rest/config.py:56
#: src/backend/rest/config.py:66 src/backend/rest/config.py:77
#: src/backend/rest/config.py:87 src/backend/rest/config.py:97
#: src/backend/rest/config.py:114 src/backend/rest/config.py:125
#: src/backend/rest/config.py:137 src/backend/rest/config.py:149
#: src/backend/rest/custom_fields.py:32 src/backend/rest/custom_fields.py:46
#: src/backend/rest/custom_fields.py:57 src/backend/rest/custom_fields.py:68
#: src/backend/rest/custom_fields.py:78 src/backend/rest/doctypes.py:31
#: src/backend/rest/doctypes.py:47 src/backend/rest/doctypes.py:58
#: src/backend/rest/doctypes.py:69 src/backend/rest/doctypes.py:80
#: src/backend/rest/forms.py:31 src/backend/rest/forms.py:44
#: src/backend/rest/forms.py:55 src/backend/rest/forms.py:88
#: src/backend/rest/forms.py:99 src/backend/rest/forms.py:111
#: src/backend/rest/history.py:39 src/backend/rest/history.py:49
#: src/backend/rest/history.py:59 src/backend/rest/inputs.py:30
#: src/backend/rest/inputs.py:43 src/backend/rest/inputs.py:53
#: src/backend/rest/inputs.py:64 src/backend/rest/inputs.py:76
#: src/backend/rest/inputs.py:88 src/backend/rest/inputs.py:100
#: src/backend/rest/inputs.py:112 src/backend/rest/inputs.py:124
#: src/backend/rest/inputs.py:137 src/backend/rest/locale.py:31
#: src/backend/rest/mailcollect.py:29 src/backend/rest/mailcollect.py:45
#: src/backend/rest/mailcollect.py:56 src/backend/rest/mailcollect.py:72
#: src/backend/rest/mailcollect.py:86 src/backend/rest/mailcollect.py:97
#: src/backend/rest/mailcollect.py:108 src/backend/rest/monitoring.py:29
#: src/backend/rest/monitoring.py:39 src/backend/rest/monitoring.py:50
#: src/backend/rest/outputs.py:31 src/backend/rest/outputs.py:44
#: src/backend/rest/outputs.py:62 src/backend/rest/outputs.py:74
#: src/backend/rest/outputs.py:86 src/backend/rest/outputs.py:99
#: src/backend/rest/outputs.py:111 src/backend/rest/outputs.py:123
#: src/backend/rest/positions_masks.py:33
#: src/backend/rest/positions_masks.py:43
#: src/backend/rest/positions_masks.py:54
#: src/backend/rest/positions_masks.py:65
#: src/backend/rest/positions_masks.py:77
#: src/backend/rest/positions_masks.py:89
#: src/backend/rest/positions_masks.py:101
#: src/backend/rest/positions_masks.py:112
#: src/backend/rest/positions_masks.py:123
#: src/backend/rest/positions_masks.py:134
#: src/backend/rest/positions_masks.py:145
#: src/backend/rest/positions_masks.py:157 src/backend/rest/privileges.py:29
#: src/backend/rest/privileges.py:39 src/backend/rest/roles.py:29
#: src/backend/rest/roles.py:39 src/backend/rest/roles.py:49
#: src/backend/rest/roles.py:60 src/backend/rest/roles.py:71
#: src/backend/rest/roles.py:81 src/backend/rest/roles.py:91
#: src/backend/rest/roles.py:101 src/backend/rest/splitter.py:30
#: src/backend/rest/splitter.py:54 src/backend/rest/splitter.py:64
#: src/backend/rest/splitter.py:74 src/backend/rest/splitter.py:85
#: src/backend/rest/splitter.py:100 src/backend/rest/splitter.py:110
#: src/backend/rest/splitter.py:121 src/backend/rest/splitter.py:135
#: src/backend/rest/splitter.py:146 src/backend/rest/splitter.py:157
#: src/backend/rest/splitter.py:168 src/backend/rest/splitter.py:179
#: src/backend/rest/splitter.py:190 src/backend/rest/splitter.py:205
#: src/backend/rest/splitter.py:208 src/backend/rest/splitter.py:226
#: src/backend/rest/splitter.py:238 src/backend/rest/splitter.py:249
#: src/backend/rest/splitter.py:260 src/backend/rest/splitter.py:270
#: src/backend/rest/status.py:31 src/backend/rest/tasks_watcher.py:30
#: src/backend/rest/user.py:29 src/backend/rest/user.py:40
#: src/backend/rest/user.py:65 src/backend/rest/user.py:75
#: src/backend/rest/user.py:107 src/backend/rest/user.py:118
#: src/backend/rest/user.py:128 src/backend/rest/user.py:138
#: src/backend/rest/user.py:155 src/backend/rest/user.py:166
#: src/backend/rest/user.py:176 src/backend/rest/verifier.py:32
#: src/backend/rest/verifier.py:55 src/backend/rest/verifier.py:66
#: src/backend/rest/verifier.py:76 src/backend/rest/verifier.py:88
#: src/backend/rest/verifier.py:100 src/backend/rest/verifier.py:111
#: src/backend/rest/verifier.py:123 src/backend/rest/verifier.py:135
#: src/backend/rest/verifier.py:147 src/backend/rest/verifier.py:159
#: src/backend/rest/verifier.py:171 src/backend/rest/verifier.py:182
#: src/backend/rest/verifier.py:201 src/backend/rest/verifier.py:220
#: src/backend/rest/verifier.py:239 src/backend/rest/verifier.py:251
#: src/backend/rest/verifier.py:262 src/backend/rest/verifier.py:284
#: src/backend/rest/verifier.py:301 src/backend/rest/verifier.py:311
#: src/backend/rest/verifier.py:323 src/backend/rest/verifier.py:335
#: src/backend/rest/verifier.py:346 src/backend/rest/verifier.py:359
#: src/backend/rest/verifier.py:370 src/backend/rest/workflow.py:31
#: src/backend/rest/workflow.py:44 src/backend/rest/workflow.py:57
#: src/backend/rest/workflow.py:70 src/backend/rest/workflow.py:82
#: src/backend/rest/workflow.py:94 src/backend/rest/workflow.py:106
#: src/backend/rest/workflow.py:118 src/backend/rest/workflow.py:131
msgid "UNAUTHORIZED_ROUTE"
msgstr "Vous n'êtes pas autorisé à accéder à cette route"

#: src/backend/rest/auth.py:45 src/backend/rest/auth.py:74
msgid "PGSQL_ERROR"
msgstr "Erreur lors de la connexion à la base de donnée"

#: src/backend/rest/auth.py:149
msgid "REQUEST_MODIFS_ERROR"
msgstr "Erreur base de données impossible d'exécuter la requête"

#: src/backend/rest/monitoring.py:55
msgid "TOKEN_IS_MANDATORY"
msgstr "Un token valide est obligatoire"

#: src/backend/rest/splitter.py:47 src/backend/rest/verifier.py:48
msgid "UNKNOW_ERROR"
msgstr "Erreur inconnue"
