# French translations for Open-Capture
# Copyright (C) 2019 ORGANIZATION
# This file is distributed under the same license as the project
# FIRST AUTHOR <nathan.cheval@edissyum.com>, 2021.
msgid ""
msgstr ""
"Project-Id-Version:  0.1\n"
"Report-Msgid-Bugs-To: nathan.cheval@edissyum.com\n"
"POT-Creation-Date: 2023-06-19 17:13+0200\n"
"PO-Revision-Date: 2019-09-02 17:48+0200\n"
"Last-Translator: Nathan CHEVAL <nathan.cheval@edissyum.com>\n"
"Language: fr\n"
"Language-Team: fr <nathan.cheval@edissyum.com>\n"
"Plural-Forms: nplurals=2; plural=(n > 1);\n"
"MIME-Version: 1.0\n"
"Content-Type: text/plain; charset=utf-8\n"
"Content-Transfer-Encoding: 8bit\n"
"Generated-By: Babel 2.12.1\n"

#: custom/edissyum/src/backend/process_queue_splitter.py:220
#: custom/edissyum/src/backend/process_queue_verifier.py:233
msgid "FILE_UPLOADED_WORKFLOW"
msgstr "Fichier téléversé avec le workflow"

#: src/backend/scripting_functions.py:31
msgid "WORFKLOW_NOT_FOUND"
msgstr "Le workflow n'existe pas"

#: src/backend/splitter_exports.py:95
msgid "OUTPUT_NOT_FOUND"
msgstr "La chaîne sortante n'existe pas"

#: src/backend/models/outputs.py:101 src/backend/splitter_exports.py:123
msgid "OUTPUT_TYPE_DOESNT_EXISTS"
msgstr "Le type de chaîne sortante n'existe aps"

#: src/backend/splitter_exports.py:170 src/backend/splitter_exports.py:272
msgid "EXPORT_PDF_ERROR"
msgstr "Erreur lors de l'export PDF"

#: src/backend/splitter_exports.py:241 src/backend/splitter_exports.py:295
msgid "EXPORT_XML_ERROR"
msgstr "Erreur lors de l'export XML"

#: src/backend/splitter_exports.py:314
msgid "CHECK_FOLDER_ERROR"
msgstr "Erreur lors de la vérification du dossier"

#: src/backend/splitter_exports.py:315
msgid "FOLDER_DOES_NOT_EXIST"
msgstr "Dossier inexistant"

#: src/backend/splitter_exports.py:333
msgid "OPENADS_ADD_DOC_ERROR"
msgstr "Erreur lors de l'envoi de document à OpenADS"

#: src/backend/verifier_exports.py:152 src/backend/verifier_exports.py:155
msgid "XML_DESTINATION_FOLDER_DOESNT_EXISTS"
msgstr "Le dossier de destination XML n'existe pas"

#: src/backend/verifier_exports.py:354 src/backend/verifier_exports.py:357
#: src/backend/verifier_exports.py:424 src/backend/verifier_exports.py:427
msgid "PDF_DESTINATION_FOLDER_DOESNT_EXISTS"
msgstr "Le dossier de destination PDF n'existe pas"

#: src/backend/verifier_exports.py:587 src/backend/verifier_exports.py:593
#: src/backend/verifier_exports.py:599
msgid "EXPORT_MEM_ERROR"
msgstr "Erreur lors de l'export vers MEM Courrier"

#: src/backend/verifier_exports.py:594
msgid "PDF_FILE_NOT_FOUND"
msgstr "Le fichier PDF est introuvable"

#: src/backend/verifier_exports.py:605
msgid "MEM_WS_INFO_WRONG"
msgstr "Les informations de connexion à MEM Courrier sont erronées"

#: src/backend/verifier_exports.py:611
msgid "MEM_WS_INFO_EMPTY"
msgstr "Les informations de connexion à MEM Courrier sont vides"

#: src/backend/classes/MEMWebServices.py:39
msgid "HOST_NOT_FOUND"
msgstr "L'URL de l'hôte n'existe pas"

#: src/backend/classes/SMTP.py:223
msgid "RESET_PASSWORD"
msgstr "Réinitialiser le mot de passe"

#: src/backend/classes/SMTP.py:225
msgid "FORGOT_EMAIL_HEADER"
msgstr ""
"Bonjour,<br/><br/>Vous avez demandé à réinitialiser le mot de passe de "
"votre compte Open-Capture.<br/><br/>Pour modifier votre mot de passe, "
"veuillez cliquer sur le lien ci-dessous :<br/><br/>"

#: src/backend/classes/SMTP.py:225
msgid "CLICK_HERE"
msgstr "Cliquez ici"

#: src/backend/classes/SMTP.py:225
msgid "FORGOT_EMAIL_FOOTER"
msgstr ""
"<br/><br/>Si vous n'êtes pas à l'origine de cette demande, merci "
"d'ignorer cet e-mail."

#: src/backend/classes/SMTP.py:242
msgid "SMTP_TEST_SEND"
msgstr "Test d'envoi de mail"

#: src/backend/classes/SMTP.py:243
msgid "SMTP_TEST_SEND_BODY"
msgstr "Ceci est un test d'envoi de mail depuis l'application Open-Capture"

#: src/backend/controllers/accounts.py:63 src/backend/models/accounts.py:61
msgid "GET_SUPPLIER_BY_ID_ERROR"
msgstr "Erreur lors de la récupération du compte tiers"

#: src/backend/controllers/accounts.py:76
msgid "GET_ADDRESS_BY_ID_ERROR"
msgstr "Erreur lors de la récupération de l'adresse"

#: src/backend/controllers/accounts.py:103
#: src/backend/controllers/accounts.py:229
msgid "UPDATE_SUPPLIER_POSITIONS_ERROR"
msgstr "Erreur lors de la mise à jour des positions du compte tiers"

#: src/backend/controllers/accounts.py:130
#: src/backend/controllers/accounts.py:260
msgid "UPDATE_SUPPLIER_PAGES_ERROR"
msgstr "Erreur lors de la mise à jour des pages du compte tiers"

#: src/backend/controllers/accounts.py:186
msgid "SUPPLIER_UPDATED"
msgstr "Mise à jour du compte tiers&nbsp<strong>%(supplier)s</strong>"

#: src/backend/controllers/accounts.py:192
#: src/backend/controllers/accounts.py:198
msgid "UPDATE_SUPPLIER_ERROR"
msgstr "Erreur lors de la mise à jour du tiers"

#: src/backend/controllers/accounts.py:284
#: src/backend/controllers/accounts.py:290
#: src/backend/controllers/accounts.py:314
#: src/backend/controllers/accounts.py:320 src/backend/models/accounts.py:127
msgid "UPDATE_ADDRESS_ERROR"
msgstr "Erreur lors de la mise à jour de l'adresse"

#: src/backend/controllers/accounts.py:344 src/backend/models/accounts.py:147
msgid "CREATE_ADDRESS_ERROR"
msgstr "Erreur lors de la création de l'adresse"

#: src/backend/controllers/accounts.py:388
msgid "SUPPLIER_CREATED"
msgstr "Création du compte tiers&nbsp<strong>%(supplier)s</strong>"

#: src/backend/controllers/accounts.py:396
#: src/backend/controllers/accounts.py:402 src/backend/models/accounts.py:167
msgid "CREATE_SUPPLIER_ERROR"
msgstr "Erreur lors de la création du compte tiers"

#: src/backend/controllers/accounts.py:403
msgid "SUPPLIER_VAT_NUMBER_ALREADY_EXISTS"
msgstr "Un compte tiers existe déjà avec ce numéro de TVA"

#: src/backend/controllers/accounts.py:440 src/backend/controllers/user.py:242
#: src/backend/controllers/user.py:272 src/backend/models/accounts.py:231
#: src/backend/models/accounts.py:254 src/backend/models/accounts.py:273
#: src/backend/models/user.py:210
msgid "GET_CUSTOMER_BY_ID_ERROR"
msgstr "Erreur lors de la récupération du compte client"

#: src/backend/controllers/accounts.py:484
msgid "CUSTOMER_UPDATED"
msgstr "Mise à jour du compte client&nbsp<strong>%(customer)s</strong>"

#: src/backend/controllers/accounts.py:489
#: src/backend/controllers/accounts.py:495 src/backend/models/accounts.py:295
msgid "UPDATE_CUSTOMER_ERROR"
msgstr "Erreur lors de la mise à jour du compte client"

#: src/backend/controllers/accounts.py:523
msgid "CUSTOMER_CREATED"
msgstr "Création du compte client&nbsp<strong>%(customer)s</strong>"

#: src/backend/controllers/accounts.py:531
#: src/backend/controllers/accounts.py:537 src/backend/models/accounts.py:315
msgid "CREATE_CUSTOMER_ERROR"
msgstr "Erreur lors de la création du compte client"

#: src/backend/controllers/accounts.py:538
msgid "CUSTOMER_VAT_NUMBER_ALREADY_EXISTS"
msgstr "Un compte client existe déjà avec ce numéro de TVA"

#: src/backend/controllers/accounts.py:554
msgid "CUSTOMER_DELETED"
msgstr "Suppression du compte client&nbsp<strong>%(customer)s</strong>"

#: src/backend/controllers/accounts.py:559
#: src/backend/controllers/accounts.py:565 src/backend/models/accounts.py:337
msgid "DELETE_CUSTOMER_ERROR"
msgstr "Erreur lors de la suppression du compte client"

#: src/backend/controllers/accounts.py:582
msgid "SUPPLIER_DELETED"
msgstr "Suppression du compte tiers&nbsp<strong>%(supplier)s</strong>"

#: src/backend/controllers/accounts.py:587
#: src/backend/controllers/accounts.py:593 src/backend/models/accounts.py:189
msgid "DELETE_SUPPLIER_ERROR"
msgstr "Erreur lors de la suppression du compte tiers"

#: src/backend/controllers/accounts.py:615
msgid "LOAD_SUPPLIER_REFERENCIAL_ERROR"
msgstr "Erreur lors du chargement du référentiel tiers"

#: src/backend/controllers/artificial_intelligence.py:79
#: src/backend/controllers/artificial_intelligence.py:438
msgid "GET_IA_MODEL_BY_ID_ERROR"
msgstr "Erreur lors de la récupération du modèle d'apprentissage"

#: src/backend/controllers/artificial_intelligence.py:103
msgid "CREATE_IA_MODEL_ERROR"
msgstr "Erreur lors de la création du modèle d'apprentissage"

#: src/backend/controllers/artificial_intelligence.py:125
msgid "DELETE_AI_MODEL"
msgstr "Suppression du modèle&nbsp;<strong>%(model)s</strong>"

#: src/backend/controllers/artificial_intelligence.py:153
msgid "UPDATE_AI_MODEL"
msgstr "Mise à jour du modèle&nbsp;<strong>%(model)s</strong>"

#: src/backend/controllers/artificial_intelligence.py:158
msgid "UPDATE_IA_MODEL_ERROR"
msgstr "Erreur lors de la mise à jour du modèle d'apprentissage"

#: src/backend/controllers/artificial_intelligence.py:218
msgid "CREATE_AI_MODEL"
msgstr "Création du modèle&nbsp;<strong>%(model)s</strong>"

#: src/backend/controllers/artificial_intelligence.py:439
#: src/backend/models/artificial_intelligence.py:59
msgid "IA_MODEL_DOESNT_EXISTS"
msgstr "Le modèle d'apprentissage n'existe pas"

#: src/backend/controllers/artificial_intelligence.py:551
msgid "RENAME_AI_MODEL_ERROR"
msgstr "Erreur lors de la modification du modèle d'intelligence artificielle"

#: src/backend/controllers/artificial_intelligence.py:552
msgid "FILE_DOESNT_EXISTS"
msgstr "Le fichier de ce modèle n'existe pas"

#: src/backend/controllers/auth.py:66 src/backend/controllers/auth.py:317
#: src/backend/controllers/auth.py:373 src/backend/controllers/auth.py:383
#: src/backend/controllers/auth.py:393 src/backend/controllers/auth.py:432
#: src/backend/controllers/auth.py:444
msgid "JWT_ERROR"
msgstr "Erreur lors de l'authentification par token"

#: src/backend/controllers/auth.py:185
msgid "RESET_JWT_ERROR"
msgstr "Erreur lors du décodage du token de réinitialisation"

#: src/backend/controllers/auth.py:194
msgid "UNIQUE_URL_JWT_ERROR"
msgstr "Erreur lors du décodage du token d'URL unique"

#: src/backend/controllers/auth.py:228
msgid "LOGOUT"
msgstr "Déconnexion de l'utilisateur"

#: src/backend/controllers/auth.py:235 src/backend/controllers/auth.py:250
#: src/backend/controllers/auth.py:296 src/backend/controllers/auth.py:349
#: src/backend/controllers/auth.py:463 src/backend/controllers/auth.py:474
#: src/backend/controllers/auth.py:484 src/backend/controllers/auth.py:511
#: src/backend/rest/auth.py:69
msgid "LOGIN_ERROR"
msgstr "Erreur lors de la connexion"

#: src/backend/controllers/auth.py:251
msgid "USER_WEBSERVICE"
msgstr ""
"L'utilisateur n'a pas le droit de se connecter à l'application "
"(utilisateur webservice)"

#: src/backend/controllers/auth.py:291 src/backend/controllers/auth.py:344
msgid "LOGIN"
msgstr "Connexion de l'utilisateur"

#: src/backend/controllers/auth.py:383
msgid "AUTHORIZATION_HEADER_INCORRECT"
msgstr "Le header d'authentification est incorrect ('Bearer' ou 'Basic' attendu)"

#: src/backend/controllers/auth.py:393
msgid "ACCOUNT_ALREADY_LOGGED"
msgstr ""
"Votre compte est déjà connecté sur un autre poste. Une seule connexion "
"est autorisée par utilisateur"

#: src/backend/controllers/auth.py:434 src/backend/controllers/auth.py:439
msgid "REST_ERROR"
msgstr "Erreur lors de l'authentification avec l'utilisateur webservice"

#: src/backend/controllers/auth.py:435
msgid "USER_DO_NOT_EXISTS"
msgstr "L'utilisateur n'existe pas en base de données"

#: src/backend/controllers/auth.py:439
msgid "PASSWORD_INCORRECT"
msgstr "Le mot de passe est incorrect"

#: src/backend/controllers/auth.py:444
msgid "VALID_TOKEN_MANDATORY"
msgstr "Un token valide est obligatoire"

#: src/backend/controllers/auth.py:475
msgid "SEVERAL_AUTH_METHODS_ENABLED"
msgstr "Plusieurs méthodes d'authentification sont activées"

#: src/backend/controllers/auth.py:499
msgid "LDAP_ERROR"
msgstr "Erreur LDAP"

#: src/backend/controllers/auth.py:500 src/backend/models/auth.py:140
msgid "NO_LDAP_CONFIGURATIONS_FOUND"
msgstr "Aucune configurations LDAP n'est disponible"

#: src/backend/controllers/auth.py:526
msgid "LOADING_METHODS_AUTH_ERROR"
msgstr "Echec lors de l'exécution de la requête"

#: src/backend/controllers/auth.py:538
msgid "DISABLE_LOGIN_METHOD_ERROR"
msgstr "Erreur lors de la désactivation de cette méthode"

#: src/backend/controllers/auth.py:550
msgid "ENABLE_LOGIN_METHOD_ERROR"
msgstr "Erreur lors de l'activation de cette méthode"

#: src/backend/controllers/auth.py:580 src/backend/controllers/auth.py:767
#: src/backend/controllers/auth.py:823 src/backend/controllers/auth.py:838
#: src/backend/controllers/auth.py:846 src/backend/controllers/auth.py:852
msgid "LDAP_CONNECTION_ERROR"
msgstr "Impossible de se connecter au serveur LDAP"

#: src/backend/controllers/auth.py:581
msgid "LOGIN_LDAP_ERROR"
msgstr "Information(s) de connexion incorrecte(s)"

#: src/backend/controllers/auth.py:755 src/backend/controllers/auth.py:761
msgid "LDAP_SYNCHRO_INFOS_ERROR"
msgstr "Information(s) de synchronisation incorrecte(s)"

#: src/backend/controllers/auth.py:757 src/backend/controllers/auth.py:763
#: src/backend/controllers/auth.py:769 src/backend/controllers/auth.py:775
#: src/backend/controllers/auth.py:781
msgid "LDAP_SYNCHRO_ERROR"
msgstr "Erreur lors de la synchronisation LDAP"

#: src/backend/controllers/auth.py:773 src/backend/controllers/auth.py:779
#: src/backend/controllers/auth.py:858 src/backend/rest/auth.py:136
msgid "INFOS_LDAP_NOT_COMPLETE"
msgstr "Informations non complètes"

#: src/backend/controllers/auth.py:821 src/backend/controllers/auth.py:836
#: src/backend/controllers/auth.py:844
msgid "BAD_CONNECTION_LDAP_INFOS"
msgstr "Information(s) incorrecte(s)"

#: src/backend/controllers/auth.py:856 src/backend/rest/auth.py:137
msgid "NOT_COMPLETE_CONNECTION_INFOS"
msgstr "Il manque une ou plusieurs informations pour établir la connexion"

#: src/backend/controllers/config.py:64
msgid "LANGUAGE_CHANGED"
msgstr "Changemement de la langue vers&nbsp;<strong>%(lang)s</strong>"

#: src/backend/controllers/config.py:79
msgid "RETRIEVE_CONFIGURATION_ERRORS"
msgstr "Erreur lors de la récupération de la configuration"

#: src/backend/controllers/config.py:109
msgid "RETRIEVE_CONFIGURATIONS_ERRORS"
msgstr "Erreur lors de la récupération des configurations"

#: src/backend/controllers/config.py:139
msgid "RETRIEVE_DOCSERVERS_ERRORS"
msgstr "Erreur lors de la récupération des docservers"

#: src/backend/controllers/config.py:177
msgid "RETRIEVE_REGEX_ERRORS"
msgstr "Erreur lors de la récupération des regex"

#: src/backend/controllers/config.py:189 src/backend/controllers/config.py:216
#: src/backend/controllers/config.py:228 src/backend/controllers/config.py:255
#: src/backend/models/config.py:199 src/backend/models/config.py:223
msgid "UPDATE_CONFIGURATION_ERROR"
msgstr "Erreur lors de la mise à jour de la configuration"

#: src/backend/controllers/config.py:190 src/backend/controllers/config.py:229
msgid "JWT_EXPIRATION_COULDNT_BE_ZERO_OR_LESS"
msgstr "La valeur d'expiration du token ne peut être inférieure à 0"

#: src/backend/controllers/config.py:211 src/backend/controllers/config.py:250
msgid "UPDATE_CONFIGURATION"
msgstr "Mise à jour de la configuration&nbsp;<strong>%(config)s</strong>"

#: src/backend/controllers/config.py:278
msgid "UPDATE_REGEX"
msgstr "Mise à jour de la regex&nbsp;<strong>%(regex)s</strong>"

#: src/backend/controllers/config.py:283 src/backend/models/config.py:245
msgid "UPDATE_REGEX_ERROR"
msgstr "Erreur lors de la mise à jour des REGEX"

#: src/backend/controllers/config.py:305
msgid "UPDATE_DOCSERVER"
msgstr "Mise à jour de la zone de stockage&nbsp;<strong>%(docserver)s</strong>"

#: src/backend/controllers/config.py:310 src/backend/models/config.py:271
msgid "UPDATE_DOCSERVER_ERROR"
msgstr "Erreur lors de la mise à jour de la docserver"

#: src/backend/controllers/config.py:352 src/backend/controllers/config.py:368
#: src/backend/controllers/config.py:373
msgid "ERROR_UPDATING_IMAGE"
msgstr "Erreur lors de la modification de l'image de connexion"

#: src/backend/controllers/config.py:353 src/backend/controllers/config.py:369
msgid "CUSTOM_IMAGE_PATH_NOT_WRITEABLE_OR_NOT_EXISTS"
msgstr "Le dossier d'image du custom n'est pas accessible"

#: src/backend/controllers/config.py:363
msgid "UPDATE_LOGIN_IMAGE"
msgstr "Modification de l'image de login"

#: src/backend/controllers/config.py:374
msgid "CUSTOM_NOT_PRESENT"
msgstr "Aucun custom n'est présent"

#: src/backend/controllers/custom_fields.py:33
#: src/backend/controllers/custom_fields.py:49
#: src/backend/controllers/custom_fields.py:62
msgid "CUSTOM_FIELDS_ERROR"
msgstr "Erreur sur les champs personnalisés"

#: src/backend/controllers/custom_fields.py:75
msgid "CUSTOM_FIELDS_DELETE_ERROR"
msgstr "Erreur lors de la suppression du champ personnalisé"

#: src/backend/controllers/doctypes.py:34
#: src/backend/controllers/doctypes.py:76 src/backend/models/doctypes.py:131
#: src/backend/models/doctypes.py:134
msgid "SET_DEFAULT_DOCTYPE_ERROR"
msgstr "Erreur lors de la modification du type de document par défaut"

#: src/backend/controllers/doctypes.py:40 src/backend/models/doctypes.py:51
msgid "ADD_DOCTYPE_ERROR"
msgstr "Erreur lors de l'ajout d'un type de document"

#: src/backend/controllers/doctypes.py:60
#: src/backend/controllers/doctypes.py:96
#: src/backend/controllers/doctypes.py:109
#: src/backend/controllers/doctypes.py:161
#: src/backend/controllers/doctypes.py:192
msgid "DOCTYPE_ERROR"
msgstr "Erreur sur les types de documents"

#: src/backend/controllers/doctypes.py:128
msgid "BUNDLESEPARATOR"
msgstr "SEPARATEUR DE LOT / BUNDLE SEPARATOR"

#: src/backend/controllers/doctypes.py:135
msgid "DOCUMENTSEPARATOR"
msgstr "SEPARATEUR DE DOCUMENT / DOCUMENT SEPARATOR"

#: src/backend/controllers/doctypes.py:154
msgid "DOCTYPESEPARATOR"
msgstr "SEPARATEUR AVEC TYPE DE DOCUMENT / SEPARATOR WITH DOCUMENT TYPE"

#: src/backend/controllers/forms.py:72 src/backend/controllers/forms.py:106
#: src/backend/controllers/forms.py:229
msgid "FORMS_ERROR"
msgstr "Erreur sur les formulaires"

#: src/backend/controllers/forms.py:101
msgid "CREATE_FORM"
msgstr "Création du formulaire&nbsp;<strong>%(form)s</strong>"

#: src/backend/controllers/forms.py:121 src/backend/controllers/forms.py:170
#: src/backend/models/forms.py:66
msgid "GET_FORM_BY_ID_ERROR"
msgstr "Erreur lors de la récupération du formulaire"

#: src/backend/controllers/forms.py:153
msgid "GET_FORM_FIELDS_BY_FORM_ID_ERROR"
msgstr "Erreur lors de la récupération des champs du formulaire"

#: src/backend/controllers/forms.py:218
msgid "UPDATE_FORM"
msgstr "Mise à jour du formulaire&nbsp;<strong>%(form)s</strong>"

#: src/backend/controllers/forms.py:223 src/backend/controllers/forms.py:381
#: src/backend/controllers/forms.py:387
msgid "UPDATE_FORMS_FIELDS_ERROR"
msgstr "Erreur lors de la mise à jour des champs du formulaire"

#: src/backend/controllers/forms.py:245
msgid "DELETE_FORM"
msgstr "Suppression du formulaire&nbsp;<strong>%(form)s</strong>"

#: src/backend/controllers/forms.py:250 src/backend/controllers/forms.py:256
msgid "DELETE_FORM_ERROR"
msgstr "Erreur lors de la suppression du formulaire"

#: src/backend/controllers/forms.py:265 src/backend/controllers/outputs.py:65
#: src/backend/controllers/positions_masks.py:165
#: src/backend/controllers/workflow.py:114
msgid "COPY_OF"
msgstr "Copie de"

#: src/backend/controllers/forms.py:286
msgid "DUPLICATE_FORM"
msgstr "Duplication du formulaire&nbsp;<strong>%(form)s</strong>"

#: src/backend/controllers/forms.py:291 src/backend/controllers/forms.py:297
msgid "DUPLICATE_FORM_ERROR"
msgstr "Erreur lors de la duplication du formulaire"

#: src/backend/controllers/forms.py:313
msgid "DISABLE_FORM"
msgstr "Désactivation du formulaire&nbsp;<strong>%(form)s</strong>"

#: src/backend/controllers/forms.py:318 src/backend/controllers/forms.py:324
msgid "DISABLE_FORM_ERROR"
msgstr "Erreur lors de la désactivation du formulaire"

#: src/backend/controllers/forms.py:340
msgid "ENABLE_FORM"
msgstr "Activation du formulaire&nbsp;<strong>%(form)s</strong>"

#: src/backend/controllers/forms.py:345 src/backend/controllers/forms.py:351
msgid "ENABLE_FORM_ERROR"
msgstr "Erreur lors de l'activation du formulaire"

#: src/backend/controllers/forms.py:367
msgid "GET_FORMS_FIELDS_ERROR"
msgstr "Erreur lors de la récupération des champs du formulaire"

#: src/backend/controllers/history.py:31
msgid "ADD_HISTORY_ERROR"
msgstr "Erreur lors de l'ajout dans l'historique"

#: src/backend/controllers/mailcollect.py:38
msgid "RETRIEVE_PROCESSES_ERROR"
msgstr "Erreur lors de la récupération des processus MailCollect"

#: src/backend/controllers/mailcollect.py:53
msgid "UPDATE_MAILCOLLECT_PROCESS"
msgstr "Mise à jour du processus MailCollect&nbsp;<strong>%(process)s</strong>"

#: src/backend/controllers/mailcollect.py:61
msgid "UPDATE_PROCESS_ERROR"
msgstr "Erreur lors de la mise à jour du processus MailCollect"

#: src/backend/controllers/mailcollect.py:76
msgid "CREATE_MAILCOLLECT_PROCESS"
msgstr "Création du processus MailCollect&nbsp;<strong>%(process)s</strong>"

#: src/backend/controllers/mailcollect.py:84
msgid "CREATE_PROCESS_ERROR"
msgstr "Erreur lors de la création d'un processus MailCollect"

#: src/backend/controllers/mailcollect.py:100
msgid "DELETE_MAILCOLLECT_PROCESS"
msgstr "Suppression du processus MailCollect&nbsp;<strong>%(process)s</strong>"

#: src/backend/controllers/mailcollect.py:105
#: src/backend/controllers/mailcollect.py:111
msgid "DELETE_MAILCOLLECT_PROCESS_ERROR"
msgstr "Erreur lors de la suppression d'un processus MailCollect"

#: src/backend/controllers/mailcollect.py:127
msgid "ENABLE_MAILCOLLECT_PROCESS"
msgstr "Activation du processus MailCollect&nbsp;<strong>%(process)s</strong>"

#: src/backend/controllers/mailcollect.py:132
#: src/backend/controllers/mailcollect.py:138
msgid "ENABLE_MAILCOLLECT_PROCESS_ERROR"
msgstr "Erreur lors de l'activation d'un processus MailCollect"

#: src/backend/controllers/mailcollect.py:154
msgid "DISABLE_MAILCOLLECT_PROCESS"
msgstr "Désactivation du processus MailCollect&nbsp;<strong>%(process)s</strong>"

#: src/backend/controllers/mailcollect.py:159
#: src/backend/controllers/mailcollect.py:165
msgid "DISABLE_MAILCOLLECT_PROCESS_ERROR"
msgstr "Erreur lors de la désactivation d'un processus MailCollect"

#: src/backend/controllers/mailcollect.py:179
#: src/backend/controllers/mailcollect.py:189
msgid "MAILCOLLECT_ERROR"
msgstr "Erreur MailCollect"

#: src/backend/controllers/outputs.py:74
msgid "DUPLICATE_OUTPUT"
msgstr "Chaîne sortante dupliquée&nbsp;<strong>%(output)s</strong>"

#: src/backend/controllers/outputs.py:79 src/backend/controllers/outputs.py:85
msgid "DUPLICATE_OUTPUT_ERROR"
msgstr "Erreur lors de la duplication de la chaîne sortante"

#: src/backend/controllers/outputs.py:114
#: src/backend/controllers/outputs.py:143
#: src/backend/controllers/outputs.py:149
msgid "UPDATE_OUTPUT_ERROR"
msgstr "Erreur lors de mise à jour de la chaîne sortante"

#: src/backend/controllers/outputs.py:115
msgid "NOT_ALLOWED_OUTPUT_PATH"
msgstr "Le chemin d'export de la chaîne sortant n'est pas autorisé"

#: src/backend/controllers/outputs.py:138
msgid "UPDATE_OUTPUT"
msgstr "Mise à jour de la chaîne sortante&nbsp;<strong>%(output)s</strong>"

#: src/backend/controllers/outputs.py:172
msgid "CREATE_OUTPUT"
msgstr "Création de la chaîne sortante&nbsp;<strong>%(output)s</strong>"

#: src/backend/controllers/outputs.py:180
msgid "CREATE_OUTPUT_ERROR"
msgstr "Erreur lors de la création de la chaîne sortante"

#: src/backend/controllers/outputs.py:193
msgid "GET_OUTPUT_BY_ID_ERROR"
msgstr "Erreur lors de la récupération de la chaîne sortante"

#: src/backend/controllers/outputs.py:206
msgid "GET_OUTPUT_TYPE_BY_ID_ERROR"
msgstr "Erreur lors de la récupération des types de chaîne sortante"

#: src/backend/controllers/outputs.py:222
msgid "DELETE_OUTPUT"
msgstr "Suppression de la chaîne sortante&nbsp;<strong>%(output)s</strong>"

#: src/backend/controllers/outputs.py:227
#: src/backend/controllers/outputs.py:233
msgid "DELETE_OUTPUT_ERROR"
msgstr "Erreur lors de la suppression de la chaîne sortante"

#: src/backend/controllers/positions_masks.py:43
#: src/backend/controllers/positions_masks.py:74
#: src/backend/controllers/positions_masks.py:123
#: src/backend/controllers/positions_masks.py:129
msgid "POSITION_MASKS_ERROR"
msgstr "Erreur sur les masques de positionnement"

#: src/backend/controllers/positions_masks.py:65
msgid "CREATE_POSITIONS_MASK"
msgstr "Création du masque de positionnement&nbsp;<strong>%(mask)s</strong>"

#: src/backend/controllers/positions_masks.py:89
msgid "GET_POSITION_MASK_BY_ID_ERROR"
msgstr "Erreur lors de la récupération du masque de positionnement"

#: src/backend/controllers/positions_masks.py:118
msgid "UPDATE_POSITIONS_MASK"
msgstr "Mise à jour du masque de positionnement&nbsp;<strong>%(mask)s</strong>"

#: src/backend/controllers/positions_masks.py:145
#: src/backend/controllers/positions_masks.py:230
msgid "DELETE_POSITIONS_MASK"
msgstr "Suppression du masque de positionnement&nbsp;<strong>%(mask)s</strong>"

#: src/backend/controllers/positions_masks.py:150
#: src/backend/controllers/positions_masks.py:156
msgid "DELETE_POSITION_MASK_ERROR"
msgstr "Erreur lors de la suppression du masque de positionnement"

#: src/backend/controllers/positions_masks.py:181
#: src/backend/controllers/positions_masks.py:187
msgid "DUPLICATE_POSITIONS_MASKS_ERROR"
msgstr "Erreur lors de la duplication du masque de positionnement"

#: src/backend/controllers/positions_masks.py:203
msgid "DISABLE_POSITIONS_MASK"
msgstr "Désactivation du masque de positionnement&nbsp;<strong>%(mask)s</strong>"

#: src/backend/controllers/positions_masks.py:208
#: src/backend/controllers/positions_masks.py:214
msgid "DISABLE_POSITION_MASK_ERROR"
msgstr "Erreur lors de désactivation du masque de positionnement"

#: src/backend/controllers/positions_masks.py:235
#: src/backend/controllers/positions_masks.py:241
msgid "ENABLE_POSITION_MASK_ERROR"
msgstr "Erreur lors de l'activation du masque de positionnement"

#: src/backend/controllers/positions_masks.py:264
msgid "UPDATE_POSITIONS_BY_POSITIONS_MASK_ID_ERROR"
msgstr "Erreur lors de la mise à jour des positions du masque de positionnement"

#: src/backend/controllers/positions_masks.py:287
msgid "UPDATE_PAGES_BY_POSITIONS_MASK_ID_ERROR"
msgstr "Erreur lors de la mise à jour des pages du masque de positionnement"

#: src/backend/controllers/positions_masks.py:305
msgid "DELETE_POSITIONS_BY_POSITION_MASK_ID_ERROR"
msgstr "Erreur lors de la suppression des positions du masque de positionnement"

#: src/backend/controllers/positions_masks.py:323
msgid "DELETE_PAGES_BY_POSITION_MASK_ID_ERROR"
msgstr "Erreur lors de la suppression des pages du masque de positionnement"

#: src/backend/controllers/privileges.py:38
#: src/backend/controllers/privileges.py:66
#: src/backend/controllers/privileges.py:94
msgid "GET_PRIVILEGES_ERROR"
msgstr "Erreur lors de la récupération des privilèges"

#: src/backend/controllers/roles.py:39 src/backend/controllers/user.py:116
#: src/backend/controllers/user.py:132 src/backend/controllers/user.py:213
#: src/backend/models/user.py:140 src/backend/models/user.py:187
msgid "GET_USER_BY_ID_ERROR"
msgstr "Erreur lors de la récupération de l'utilisateur"

#: src/backend/controllers/roles.py:49 src/backend/controllers/roles.py:168
msgid "GET_ROLE_BY_ID_ERROR"
msgstr "Erreur lors de la récupération du rôle"

#: src/backend/controllers/roles.py:88
msgid "UPDATE_ROLE"
msgstr "Mise à jour du rôle&nbsp;<strong>%(role)s</strong>"

#: src/backend/controllers/roles.py:93 src/backend/controllers/roles.py:99
#: src/backend/controllers/roles.py:149 src/backend/controllers/roles.py:155
#: src/backend/models/roles.py:85
msgid "UPDATE_ROLE_ERROR"
msgstr "Erreur lors de la mise à jour du rôle"

#: src/backend/controllers/roles.py:120
msgid "CREATE_ROLE"
msgstr "Création du rôle&nbsp;<strong>%(role)s</strong>"

#: src/backend/controllers/roles.py:129 src/backend/models/roles.py:105
msgid "CREATE_ROLE_ERROR"
msgstr "Erreur lors de la création du rôle"

#: src/backend/controllers/roles.py:184
msgid "DELETE_ROLE"
msgstr "Suppression du rôle&nbsp;<strong>%(role)s</strong>"

#: src/backend/controllers/roles.py:189 src/backend/controllers/roles.py:195
msgid "DELETE_ROLE_ERROR"
msgstr "Erreur lors de la suppression du rôle"

#: src/backend/controllers/roles.py:209 src/backend/controllers/roles.py:215
msgid "DISABLE_ROLE_ERROR"
msgstr "Erreur lors de la désactivation du rôle"

#: src/backend/controllers/roles.py:229 src/backend/controllers/roles.py:235
msgid "ENABLE_ROLE_ERROR"
msgstr "Erreur lors de l'activation du rôle"

#: src/backend/controllers/smtp.py:49
msgid "SMTP_TEST_SEND_EMAIL_ERROR"
msgstr "Erreur lors de l'envoi du mail de test"

#: src/backend/controllers/smtp.py:55
msgid "SMTP_TEST_CONNECTION_ERROR"
msgstr "Erreur lors de la connexion SMTP"

#: src/backend/controllers/splitter.py:114
msgid "LOAD_METADATA_ERROR"
msgstr "Erreur du chargement des métadonnées"

#: src/backend/controllers/splitter.py:170
#: src/backend/controllers/verifier.py:122
msgid "AT"
msgstr "à"

#: src/backend/controllers/splitter.py:194
msgid "FORM_UNDEFINED"
msgstr "Formulaire non défini"

#: src/backend/controllers/splitter.py:197
msgid "CUSTOMER_UNDEFINED"
msgstr "Compte client non défini"

#: src/backend/controllers/splitter.py:255
#: src/backend/controllers/splitter.py:286
msgid "BATCH_NOT_FOUND"
msgstr "Lot non trouvé"

#: src/backend/controllers/splitter.py:256
#: src/backend/controllers/splitter.py:287
msgid "BATCH_ID_NOT_FOUND"
msgstr "Lot %(id)s non trouvé"

#: src/backend/controllers/splitter.py:270
msgid "DELETE_BATCH_SUCCESS"
msgstr "Suppression du lot n°<strong>%(batch_id)s</strong>"

#: src/backend/controllers/splitter.py:275
#: src/backend/controllers/splitter.py:296
#: src/backend/controllers/verifier.py:696
msgid "UPDATE_STATUS_ERROR"
msgstr "Erreur lors de la mise à jour du statut"

#: src/backend/controllers/splitter.py:331
#: src/backend/controllers/verifier.py:402
msgid "REMOVE_LOCK_BY_USER_ID_ERROR"
msgstr "Erreur lors de la suppression du verrou"

#: src/backend/controllers/splitter.py:433
msgid "ADD_DOCUMENT_ERROR"
msgstr "Erreur lors de l'ajout d'un document"

#: src/backend/controllers/splitter.py:459
msgid "UPDATE_BATCH_ERROR"
msgstr "Erreur lors de la mise à jour du lot"

#: src/backend/controllers/splitter.py:472
msgid "UPDATE_DOCUMENTS_ERROR"
msgstr "Erreur lors de la mise à jour du document"

#: src/backend/controllers/splitter.py:485
#: src/backend/controllers/verifier.py:379
#: src/backend/controllers/verifier.py:385
msgid "UPDATE_DOCUMENT_ERROR"
msgstr "Erreur lors de la mise à jour du document"

#: src/backend/controllers/splitter.py:500
#: src/backend/controllers/splitter.py:521
#: src/backend/controllers/splitter.py:536
#: src/backend/controllers/splitter.py:551
msgid "UPDATE_PAGES_ERROR"
msgstr "Erreur lors de la modification des pages"

#: src/backend/controllers/splitter.py:565
msgid "CMIS_CONNECTION_ERROR"
msgstr "Erreur lors de la connexion CMIS"

#: src/backend/controllers/splitter.py:578
msgid "OPENADS_CONNECTION_ERROR"
msgstr "Erreur lors de la connexion OpenADS"

#: src/backend/controllers/splitter.py:678
#: src/backend/controllers/verifier.py:675 src/backend/models/splitter.py:572
#: src/backend/models/verifier.py:194
msgid "GET_TOTALS_ERROR"
msgstr "Erreur lors de la récupération des totaux"

#: src/backend/controllers/splitter.py:777
msgid "GET_BATCH_OUTPUTS_ERROR"
msgstr "Erreur lors de la récupération du workflow"

#: src/backend/controllers/status.py:31
msgid "RETRIEVES_STATUS_ERROR"
msgstr "Erreur lors de la récupération des status"

#: src/backend/controllers/user.py:67
msgid "CREATE_USER"
msgstr "Création de l'utilisateur&nbsp;<strong>%(user)s</strong>"

#: src/backend/controllers/user.py:72
msgid "CREATE_USER_ERROR"
msgstr "Erreur lors de la création de l'utilisateur"

#: src/backend/controllers/user.py:149
msgid "GET_USER_BY_USERNAME_ERROR"
msgstr "Erreur lors de la récupération de l'utilisateur"

#: src/backend/controllers/user.py:175
msgid "USER_FORGOT_SUCCESS"
msgstr ""
"Envoi d'email de réinitialisation de mot de passe pour "
"l'utilisateur&nbsp;<strong>%(user)s</strong>"

#: src/backend/controllers/user.py:180
msgid "SEND_EMAIL_FORGOT_PASSWORD_ERROR"
msgstr "Erreur lors de l'envoi de l'email de réinitialisation du mot de passe"

#: src/backend/controllers/user.py:203
msgid "USER_RESET_PASSWORD_SUCCESS"
msgstr ""
"Mot de passe de l'utilisateur&nbsp;<strong>%(user)s</strong> réinitialisé"
" avec succès"

#: src/backend/controllers/user.py:207 src/backend/controllers/user.py:212
msgid "RESET_PASSWORD_ERROR"
msgstr "Erreur lors de la réinitilisation du mot de passe"

#: src/backend/controllers/user.py:208
msgid "RESET_TOKEN_MISMATCH"
msgstr "Le token de réinitialisation est invalide. Il est peut être expiré"

#: src/backend/controllers/user.py:293
msgid "UPDATE_PROFILE"
msgstr "Mise à jour du profile"

#: src/backend/controllers/user.py:294
msgid "ERROR_OLD_PASSWORD_NOT_MATCH"
msgstr "L'ancien mot de passe ne corresponds pas"

#: src/backend/controllers/user.py:300
msgid "UPDATE_USER"
msgstr "Mise à jour de l'utilisateur"

#: src/backend/controllers/user.py:301
msgid "ERROR_PASSWORD_NOT_MATCH"
msgstr "Les mots de passes ne correspondent pas"

#: src/backend/controllers/user.py:331
msgid "USER_UPDATED"
msgstr "Mise à jour du compte utilisateur&nbsp<strong>%(user)s</strong>"

#: src/backend/controllers/user.py:336 src/backend/controllers/user.py:342
#: src/backend/models/user.py:255 src/backend/models/user.py:321
msgid "UPDATE_USER_ERROR"
msgstr "Erreur lors de la mise à jour de l'utilisateur"

#: src/backend/controllers/user.py:358
msgid "DELETE_USER"
msgstr "Suppression de l'utilisateur&nbsp;<strong>%(user)s</strong>"

#: src/backend/controllers/user.py:366 src/backend/controllers/user.py:372
msgid "DELETE_USER_ERROR"
msgstr "Erreur lors de la suppression de l'utilisateur"

#: src/backend/controllers/user.py:388
msgid "DISABLE_USER"
msgstr "Désactivation de l'utilisateur&nbsp;<strong>%(user)s</strong>"

#: src/backend/controllers/user.py:396 src/backend/controllers/user.py:402
msgid "DISABLE_USER_ERROR"
msgstr "Erreur lors de désactiver de l'utilisateur"

#: src/backend/controllers/user.py:418
msgid "ENABLE_USER"
msgstr "Activation de l'utilisateur&nbsp;<strong>%(user)s</strong>"

#: src/backend/controllers/user.py:426 src/backend/controllers/user.py:432
msgid "ENABLE_USER_ERROR"
msgstr "Erreur lors de l'activation de l'utilisateur"

#: src/backend/controllers/user.py:449 src/backend/controllers/user.py:455
#: src/backend/models/user.py:277
msgid "UPDATE_CUSTOMERS_USER_ERROR"
msgstr "Erreur lors de la mise à jour des comptes clients de l'utilisateur"

#: src/backend/controllers/user.py:470 src/backend/controllers/user.py:477
#: src/backend/models/user.py:299
msgid "UPDATE_FORMS_USER_ERROR"
msgstr "Erreur lors de la mise à jour des formulaires de l'utilisateur"

#: src/backend/controllers/verifier.py:86 src/backend/models/splitter.py:219
#: src/backend/models/verifier.py:40
msgid "GET_DOCUMENT_BY_ID_ERROR"
msgstr "Erreur lors de la récupération du document"

#: src/backend/controllers/verifier.py:103 src/backend/models/verifier.py:64
msgid "GET_DOCUMENT_ID_AND_STATUS_BY_TOKEN_ERROR"
msgstr "Erreur lors de la récupération du document par token"

#: src/backend/controllers/verifier.py:104
msgid "GET_DOCUMENT_ID_AND_STATUS_BY_TOKEN_ERROR_MESSAGE"
msgstr "Aucun document trouvé avec ce token"

#: src/backend/controllers/verifier.py:217
#: src/backend/controllers/verifier.py:319
msgid "UPDATE_DOCUMENT_POSITIONS_ERROR"
msgstr "Erreur lors de la mise à jour des positions du document"

#: src/backend/controllers/verifier.py:240
#: src/backend/controllers/verifier.py:337
msgid "UPDATE_DOCUMENT_PAGES_ERROR"
msgstr "Erreur lors de la mise à jour des pages du document"

#: src/backend/controllers/verifier.py:263
#: src/backend/controllers/verifier.py:281
msgid "UPDATE_DOCUMENT_DATA_ERROR"
msgstr "Erreur lors de la mise à jour des données du document"

#: src/backend/controllers/verifier.py:353
msgid "DELETE_DOCUMENT_SUCCESS"
msgstr "Suppression du document n°<strong>%(document_id)s</strong>"

#: src/backend/controllers/verifier.py:358
#: src/backend/controllers/verifier.py:364
msgid "DELETE_DOCUMENT_ERROR"
msgstr "Erreur lors de la suppression du document"

#: src/backend/controllers/verifier.py:568
#: src/backend/controllers/verifier.py:571
#: src/backend/controllers/verifier.py:588
#: src/backend/controllers/verifier.py:614
#: src/backend/controllers/verifier.py:615
msgid "API_INSEE_ERROR_CONNEXION"
msgstr "Erreur lors de la connexion à l'api de l'INSEE"

#: src/backend/controllers/verifier.py:645
msgid "VAT_NOT_VALID"
msgstr "Numéro de TVA invalide"

#: src/backend/controllers/verifier.py:652
#: src/backend/controllers/verifier.py:653
msgid "VAT_API_ERROR"
msgstr "Impossible de joindre l'API de vérification du numéro de TVA"

#: src/backend/controllers/verifier.py:686
msgid "DOCUMENT_NOT_FOUND"
msgstr "Document non trouvé"

#: src/backend/controllers/verifier.py:687
msgid "DOCUMENT_ID_NOT_FOUND"
msgstr "Document %(id)s non trouvée"

#: src/backend/controllers/workflow.py:58
#: src/backend/controllers/workflow.py:67
#: src/backend/controllers/workflow.py:74
msgid "WORKFLOW_FOLDER_CREATION_ERROR"
msgstr "Erreur lors de la création du dossier de travail"

#: src/backend/controllers/workflow.py:59
msgid "FOLDER_NOT_ALLOWED_ERROR"
msgstr "Le chemin de capture n'est pas autorisé"

#: src/backend/controllers/workflow.py:68
#: src/backend/controllers/workflow.py:329
msgid "CAN_NOT_CREATE_FOLDER_PERMISSION_ERROR"
msgstr "Problème de permissions pour créer le dossier"

#: src/backend/controllers/workflow.py:75
msgid "CAN_NOT_ACCESS_FOLDER_PERMISSION_ERROR"
msgstr "Impossible d'accéder au dossier de travail"

#: src/backend/controllers/workflow.py:89
msgid "GET_WORKFLOW_BY_ID_ERROR"
msgstr "Erreur lors de la récupération du workflow"

#: src/backend/controllers/workflow.py:102
msgid "GET_WORKFLOW_BY_WORKFLOW_ID_ERROR"
msgstr "Erreur lors de la récupération du workflow"

#: src/backend/controllers/workflow.py:127
msgid "DUPLICATE_WORKFLOW"
msgstr "Duplication du workflow&nbsp;<strong>%(workflow)s</strong>"

#: src/backend/controllers/workflow.py:132
#: src/backend/controllers/workflow.py:138
msgid "DUPLICATE_WORKFLOW_ERROR"
msgstr "Erreur lors de la duplication du workflow"

#: src/backend/controllers/workflow.py:163
#: src/backend/controllers/workflow.py:175
#: src/backend/controllers/workflow.py:186
#: src/backend/controllers/workflow.py:210
msgid "CREATE_WORKFLOW_ERROR"
msgstr "Erreur lors de la création du workflow"

#: src/backend/controllers/workflow.py:164
#: src/backend/controllers/workflow.py:220
msgid "NOT_ALLOWED_INPUT_PATH"
msgstr "Le chemin de capture de la chaîne entrante n'est pas autorisé"

#: src/backend/controllers/workflow.py:176
msgid "WORKFLOW_ID_ALREADY_EXISTS"
msgstr "Le libellé technique du workflow existe déjà"

#: src/backend/controllers/workflow.py:187
msgid "INPUT_FOLDER_ALREADY_EXISTS"
msgstr "Le chemin de capture est déjà paramétré dans une autre chaîne entrante"

#: src/backend/controllers/workflow.py:202
msgid "CREATE_WORKFLOW"
msgstr "Création du workflow&nbsp;<strong>%(workflow)s</strong>"

#: src/backend/controllers/workflow.py:219
#: src/backend/controllers/workflow.py:247
#: src/backend/controllers/workflow.py:253
msgid "UPDATE_WORKFLOW_ERROR"
msgstr "Erreur lors de la mise à jour du workflow"

#: src/backend/controllers/workflow.py:242
msgid "UPDATE_WORKFLOW"
msgstr "Mise à jour du workflow&nbsp;<strong>%(workflow)s</strong>"

#: src/backend/controllers/workflow.py:270
msgid "DELETE_WORKFLOW"
msgstr "Suppression du workflow&nbsp;<strong>%(workflow)s</strong>"

#: src/backend/controllers/workflow.py:275
#: src/backend/controllers/workflow.py:281
msgid "DELETE_WORKFLOW_ERROR"
msgstr "Erreur lors de la suppression du workflow"

#: src/backend/controllers/workflow.py:328
#: src/backend/controllers/workflow.py:350
msgid "FS_WATCHER_CREATION_ERROR"
msgstr "Erreur lors de la création des paramètres du fs watcher"

#: src/backend/controllers/workflow.py:351
#: src/backend/controllers/workflow.py:404
msgid "FS_WATCHER_CONFIG_DOESNT_EXIST"
msgstr "La configuration du fs watcher est introuvable"

#: src/backend/controllers/workflow.py:356
msgid "SCRIPT_SAMPLE_DOESNT_EXISTS"
msgstr "Le script d'exemple n'existe pas"

#: src/backend/controllers/workflow.py:362
msgid "SCRIPT_FOLDER_DOESNT_EXISTS"
msgstr "Le dossier des scripts n'existe pas"

#: src/backend/controllers/workflow.py:403
msgid "FS_WATCHER_DELETION_ERROR"
msgstr "Erreur lors de la suppression de l'entrée du fs watcher"

#: src/backend/models/accounts.py:105
msgid "SUPPLIER_UPDATE_ERROR"
msgstr "Erreur lors de la mise à jour du tiers"

#: src/backend/models/artificial_intelligence.py:80
msgid "IA_MODEL_CREATE_ERROR"
msgstr "Erreur lors de la création du modèle d'apprentissage"

#: src/backend/models/artificial_intelligence.py:101
msgid "IA_MODEL_UPDATE_ERROR"
msgstr "Erreur lors de la modification du modèle d'apprentissage"

#: src/backend/models/auth.py:43 src/backend/models/auth.py:101
#: src/backend/models/user.py:43 src/backend/rest/auth.py:70
msgid "BAD_USERNAME"
msgstr "Mauvais nom de compte"

#: src/backend/models/auth.py:45 src/backend/models/user.py:45
msgid "BAD_PASSWORD"
msgstr "Mauvais mot de passe"

#: src/backend/models/auth.py:47
msgid "USER_DELETED"
msgstr "Utilisateur supprimé"

#: src/backend/models/auth.py:49
msgid "USER_DISABLED"
msgstr "Utilisateur desactivé"

#: src/backend/models/auth.py:70 src/backend/models/auth.py:80
#: src/backend/models/roles.py:61
msgid "ROLE_DOESNT_EXISTS"
msgstr "Le rôle n'existe pas"

#: src/backend/models/auth.py:165
msgid "UPDATE_LOGIN_METHOD_ERROR"
msgstr "Erreur lors de la mise à jour de la méthode d'authentification"

#: src/backend/models/auth.py:211
msgid "DISABLE_LOGIN_METHOD_DATA_ERROR"
msgstr "Erreur lors de la désactivation de cette méthode d'authentification"

#: src/backend/models/auth.py:233
msgid "ENABLE_LOGIN_METHOD_DATA_ERROR"
msgstr "Erreur lors de l'activation de cette méthode d'authentification"

#: src/backend/models/custom_fields.py:57
msgid "ADD_CUSTOM_FIELD_ERROR"
msgstr "Erreur lors de la création du champ custom"

#: src/backend/models/custom_fields.py:60
msgid "CUSTOM_FIELD_ALREADY_EXIST"
msgstr "Le champ custom existe déjà"

#: src/backend/models/custom_fields.py:110
msgid "UPDATE_CUSTOM_FIELDS_ERROR"
msgstr "Erreur lors de la mise à jour du champ custom"

#: src/backend/models/custom_fields.py:133
msgid "DELETE_CUSTOM_FIELDS_ERROR"
msgstr "Erreur lors de la suppression du champ custom"

#: src/backend/models/doctypes.py:54
msgid "DOCTYPE_ALREADY_EXIST"
msgstr "Le type de document existe déjà"

#: src/backend/models/doctypes.py:100
msgid "UPDATE_DOCTYPE_ERROR"
msgstr "Erreur lors de la mise à jour du type de document"

#: src/backend/models/forms.py:45
msgid "GET_FORMS_ERROR"
msgstr "Erreur lors de la récupération des formulaires"

#: src/backend/models/forms.py:89
msgid "GET_FORM_SETTINGS_BY_ID_ERROR"
msgstr "Erreur lors de la récupération des paramètres du formulaire"

#: src/backend/models/forms.py:112
msgid "GET_DEFAULT_FORM_ERROR"
msgstr "Erreur lors de la récupération du formulaire par défaut"

#: src/backend/models/forms.py:136
msgid "UPDATE_FORM_ERROR"
msgstr "Erreur lors de la mise à jour du formulaire"

#: src/backend/models/forms.py:158
msgid "UPDATE_FORM_FIELDS_ERROR"
msgstr "Erreur lors de la mise à jour des champs du formulaire"

#: src/backend/models/forms.py:215
msgid "ADD_FORM_ERROR"
msgstr "Erreur lors de la création du formulaire"

#: src/backend/models/forms.py:218
msgid "FORM_LABEL_ALREADY_EXIST"
msgstr "Le libellé de formulaire existe déjà"

#: src/backend/models/mailcollect.py:85
msgid "MAILCOLLECT_PROCESS_UPDATE_ERROR"
msgstr "Erreur lors de la mise à jour d'un processus MailCollect"

#: src/backend/models/outputs.py:78
msgid "OUTPUT_DOESNT_EXISTS"
msgstr "La chaîne sortante n'existe pas"

#: src/backend/models/outputs.py:125
msgid "OUTPUT_UPDATE_ERROR"
msgstr "Erreur lors de la mise à jour de la chaîne sortante"

#: src/backend/models/outputs.py:145
msgid "OUTPUT_CREATE_ERROR"
msgstr "Erreur lors de la création de la chaîne sortante"

#: src/backend/models/positions_masks.py:63
msgid "GET_POSITIONS_MASKS_BY_ID_ERROR"
msgstr "Erreur lors de la récupération du masque de positionnement"

#: src/backend/models/positions_masks.py:87
msgid "UPDATE_POSITIONS_MASKS_ERROR"
msgstr "Erreur lors de la mise à jour du masque de positionnement"

#: src/backend/models/positions_masks.py:109
msgid "UPDATE_POSITIONS_MASKS_FIELDS_ERROR"
msgstr "Erreur lors de la mise à jour des champs du masque de positionnement"

#: src/backend/models/positions_masks.py:144
msgid "ADD_POSITIONS_MASKS_ERROR"
msgstr "Erreur lors de la création du masque de positionnement"

#: src/backend/models/positions_masks.py:147
msgid "POSITIONS_MASK_LABEL_ALREADY_EXIST"
msgstr "Le libellé du masque de positionnement existe déjà"

#: src/backend/models/privileges.py:38 src/backend/models/privileges.py:59
#: src/backend/models/privileges.py:83
msgid "ERROR_RETRIEVING_PRIVILEGES"
msgstr "Erreur lors de la récupération des privilèges"

#: src/backend/models/roles.py:127
msgid "ROLE_PRIVILEGES_UPDATE_ERROR"
msgstr "Erreur lors de la mise à jour des privilèges du rôle"

#: src/backend/models/roles.py:149
msgid "ROLE_PRIVILEGES_CREATE_ERROR"
msgstr "Erreur lors de la création des privilèges du rôle"

#: src/backend/models/splitter.py:78
msgid "GET_MAX_SPLIT_INDEX_ERROR"
msgstr "Erreur lors de l'obtention de l'index du Splitter"

#: src/backend/models/splitter.py:125
msgid "UPDATE_SETTINGS_ERROR"
msgstr "Erreur lors de la mise à jour des paramètres du Splitter"

#: src/backend/models/splitter.py:150
msgid "INSERT_PAGE_ERROR"
msgstr "Erreur lors de l'insertion des pages du Splitter"

#: src/backend/models/splitter.py:244
msgid "GET_DOCUMENTS_ERROR"
msgstr "Erreur lors de la récupération des documents du Splitter"

#: src/backend/models/splitter.py:266 src/backend/models/splitter.py:289
msgid "GET_PAGES_ERROR"
msgstr "Erreur lors de l'obtention des pages du Splitter"

#: src/backend/models/splitter.py:311
msgid "GET_MAX_SOURCE_PAGE_VALUE_ERROR"
msgstr "Erreur lors de l'obtention de la valeur des pages source du Splitter"

#: src/backend/models/splitter.py:334
msgid "GET_DOCUMENT_ERROR"
msgstr "Erreur lors de la récupération du document"

#: src/backend/models/splitter.py:356
msgid "GET_DOCUMENT_MAX_SPLIT_INDEX_ERROR"
msgstr "Erreur lors de l'obtention de l'index maximum du Splitter"

#: src/backend/models/status.py:40
msgid "NO_STATUS"
msgstr "Aucun status existant"

#: src/backend/models/user.py:47
msgid "USER"
msgstr "L'utilisateur"

#: src/backend/models/user.py:47
msgid "ALREADY_REGISTERED"
msgstr "est déjà enregistré"

#: src/backend/models/user.py:163
msgid "GET_USER_BY_MAIL_ERROR"
msgstr "Aucun utilisateur asssocié à cette addresse email"

#: src/backend/models/user.py:232
msgid "GET_FORMS_BY_USER_ID_ERROR"
msgstr "Erreur lors de la récupération des formulaires de l'utilisateur"

#: src/backend/models/verifier.py:127 src/backend/models/verifier.py:148
msgid "DOCUMENT_UPDATE_ERROR"
msgstr "Erreur lors de la mise à jour du document"

#: src/backend/models/workflow.py:60 src/backend/models/workflow.py:83
msgid "WORKFLOW_DOESNT_EXISTS"
msgstr "Le workflow n'existe pas"

#: src/backend/models/workflow.py:105
msgid "WORKFLOW_CREATE_ERROR"
msgstr "Erreur lors de la création du modèle workflow"

#: src/backend/models/workflow.py:127
msgid "WORKFLOW_UPDATE_ERROR"
msgstr "Erreur lors de la modification du workflow"

#: src/backend/rest/accounts.py:35 src/backend/rest/accounts.py:45
#: src/backend/rest/accounts.py:58 src/backend/rest/accounts.py:69
#: src/backend/rest/accounts.py:82 src/backend/rest/accounts.py:95
#: src/backend/rest/accounts.py:108 src/backend/rest/accounts.py:120
#: src/backend/rest/accounts.py:133 src/backend/rest/accounts.py:153
#: src/backend/rest/accounts.py:164 src/backend/rest/accounts.py:175
#: src/backend/rest/accounts.py:186 src/backend/rest/accounts.py:206
#: src/backend/rest/accounts.py:226 src/backend/rest/accounts.py:238
#: src/backend/rest/accounts.py:248 src/backend/rest/accounts.py:259
#: src/backend/rest/accounts.py:271 src/backend/rest/accounts.py:282
#: src/backend/rest/accounts.py:326
#: src/backend/rest/artificial_intelligence.py:30
#: src/backend/rest/artificial_intelligence.py:40
#: src/backend/rest/artificial_intelligence.py:51
#: src/backend/rest/artificial_intelligence.py:61
#: src/backend/rest/artificial_intelligence.py:72
#: src/backend/rest/artificial_intelligence.py:86
#: src/backend/rest/artificial_intelligence.py:101
#: src/backend/rest/artificial_intelligence.py:113 src/backend/rest/auth.py:91
#: src/backend/rest/auth.py:117 src/backend/rest/auth.py:127
#: src/backend/rest/auth.py:147 src/backend/rest/auth.py:158
#: src/backend/rest/auth.py:181 src/backend/rest/auth.py:192
#: src/backend/rest/config.py:31 src/backend/rest/config.py:41
#: src/backend/rest/config.py:51 src/backend/rest/config.py:61
#: src/backend/rest/config.py:72 src/backend/rest/config.py:82
#: src/backend/rest/config.py:92 src/backend/rest/config.py:109
#: src/backend/rest/config.py:120 src/backend/rest/config.py:131
#: src/backend/rest/config.py:143 src/backend/rest/custom_fields.py:32
#: src/backend/rest/custom_fields.py:46 src/backend/rest/custom_fields.py:57
#: src/backend/rest/custom_fields.py:68 src/backend/rest/custom_fields.py:78
#: src/backend/rest/doctypes.py:31 src/backend/rest/doctypes.py:47
#: src/backend/rest/doctypes.py:58 src/backend/rest/doctypes.py:69
#: src/backend/rest/doctypes.py:80 src/backend/rest/forms.py:32
#: src/backend/rest/forms.py:46 src/backend/rest/forms.py:58
#: src/backend/rest/forms.py:91 src/backend/rest/forms.py:102
#: src/backend/rest/forms.py:114 src/backend/rest/forms.py:125
#: src/backend/rest/forms.py:137 src/backend/rest/forms.py:148
#: src/backend/rest/forms.py:159 src/backend/rest/forms.py:170
#: src/backend/rest/forms.py:182 src/backend/rest/history.py:39
#: src/backend/rest/history.py:49 src/backend/rest/history.py:59
#: src/backend/rest/locale.py:31 src/backend/rest/mailcollect.py:29
#: src/backend/rest/mailcollect.py:45 src/backend/rest/mailcollect.py:56
#: src/backend/rest/mailcollect.py:72 src/backend/rest/mailcollect.py:86
#: src/backend/rest/mailcollect.py:97 src/backend/rest/mailcollect.py:108
#: src/backend/rest/monitoring.py:29 src/backend/rest/monitoring.py:40
#: src/backend/rest/monitoring.py:50 src/backend/rest/monitoring.py:61
#: src/backend/rest/outputs.py:31 src/backend/rest/outputs.py:44
#: src/backend/rest/outputs.py:63 src/backend/rest/outputs.py:75
#: src/backend/rest/outputs.py:87 src/backend/rest/outputs.py:100
#: src/backend/rest/outputs.py:112 src/backend/rest/outputs.py:124
#: src/backend/rest/positions_masks.py:33
#: src/backend/rest/positions_masks.py:43
#: src/backend/rest/positions_masks.py:54
#: src/backend/rest/positions_masks.py:65
#: src/backend/rest/positions_masks.py:77
#: src/backend/rest/positions_masks.py:89
#: src/backend/rest/positions_masks.py:101
#: src/backend/rest/positions_masks.py:112
#: src/backend/rest/positions_masks.py:123
#: src/backend/rest/positions_masks.py:134
#: src/backend/rest/positions_masks.py:145
#: src/backend/rest/positions_masks.py:157 src/backend/rest/privileges.py:29
#: src/backend/rest/privileges.py:39 src/backend/rest/roles.py:43
#: src/backend/rest/roles.py:53 src/backend/rest/roles.py:64
#: src/backend/rest/roles.py:75 src/backend/rest/roles.py:85
#: src/backend/rest/roles.py:95 src/backend/rest/roles.py:105
#: src/backend/rest/splitter.py:30 src/backend/rest/splitter.py:52
#: src/backend/rest/splitter.py:62 src/backend/rest/splitter.py:72
#: src/backend/rest/splitter.py:83 src/backend/rest/splitter.py:98
#: src/backend/rest/splitter.py:109 src/backend/rest/splitter.py:119
#: src/backend/rest/splitter.py:130 src/backend/rest/splitter.py:144
#: src/backend/rest/splitter.py:155 src/backend/rest/splitter.py:166
#: src/backend/rest/splitter.py:177 src/backend/rest/splitter.py:196
#: src/backend/rest/splitter.py:207 src/backend/rest/splitter.py:222
#: src/backend/rest/splitter.py:225 src/backend/rest/splitter.py:243
#: src/backend/rest/splitter.py:255 src/backend/rest/splitter.py:266
#: src/backend/rest/splitter.py:277 src/backend/rest/splitter.py:287
#: src/backend/rest/splitter.py:298 src/backend/rest/status.py:31
#: src/backend/rest/user.py:29 src/backend/rest/user.py:40
#: src/backend/rest/user.py:65 src/backend/rest/user.py:75
#: src/backend/rest/user.py:107 src/backend/rest/user.py:118
#: src/backend/rest/user.py:128 src/backend/rest/user.py:138
#: src/backend/rest/user.py:155 src/backend/rest/user.py:166
#: src/backend/rest/user.py:176 src/backend/rest/verifier.py:45
#: src/backend/rest/verifier.py:96 src/backend/rest/verifier.py:108
#: src/backend/rest/verifier.py:129 src/backend/rest/verifier.py:142
#: src/backend/rest/verifier.py:154 src/backend/rest/verifier.py:166
#: src/backend/rest/verifier.py:179 src/backend/rest/verifier.py:192
#: src/backend/rest/verifier.py:205 src/backend/rest/verifier.py:218
#: src/backend/rest/verifier.py:230 src/backend/rest/verifier.py:241
#: src/backend/rest/verifier.py:260 src/backend/rest/verifier.py:279
#: src/backend/rest/verifier.py:299 src/backend/rest/verifier.py:311
#: src/backend/rest/verifier.py:323 src/backend/rest/verifier.py:346
#: src/backend/rest/verifier.py:364 src/backend/rest/verifier.py:376
#: src/backend/rest/verifier.py:387 src/backend/rest/verifier.py:400
#: src/backend/rest/verifier.py:413 src/backend/rest/verifier.py:424
#: src/backend/rest/verifier.py:437 src/backend/rest/verifier.py:448
#: src/backend/rest/workflow.py:32 src/backend/rest/workflow.py:45
#: src/backend/rest/workflow.py:58 src/backend/rest/workflow.py:71
#: src/backend/rest/workflow.py:83 src/backend/rest/workflow.py:95
#: src/backend/rest/workflow.py:107 src/backend/rest/workflow.py:119
#: src/backend/rest/workflow.py:132 src/backend/rest/workflow.py:145
#: src/backend/rest/workflow.py:156
msgid "UNAUTHORIZED_ROUTE"
msgstr "Vous n'êtes pas autorisé à accéder à cette route"

#: src/backend/rest/auth.py:45 src/backend/rest/auth.py:74
msgid "PGSQL_ERROR"
msgstr "Erreur lors de la connexion à la base de donnée"

#: src/backend/rest/auth.py:163
msgid "REQUEST_MODIFS_ERROR"
msgstr "Erreur base de données impossible d'exécuter la requête"

#: src/backend/rest/monitoring.py:66 src/backend/rest/verifier.py:121
msgid "TOKEN_IS_MANDATORY"
msgstr "Un token valide est obligatoire"

#: src/backend/rest/splitter.py:45 src/backend/rest/verifier.py:89
msgid "UNKNOW_ERROR"
msgstr "Erreur inconnue"

#: src/backend/rest/verifier.py:50
msgid "VERIFIER_UPLOAD_ERROR"
msgstr "Erreur lors de l'upload de fichier(s)"

#: src/backend/rest/verifier.py:51
msgid "WORKFLOW_ID_IS_MANDATORY"
msgstr "L'identifiant du workflow est obligatoire"

#: src/backend/rest/verifier.py:84
msgid "UNIQUE_URL_TOKEN_GENERATION_ERROR"
msgstr "Erreur lors de la génération du token de l'URL unique"

#: src/backend/rest/verifier.py:85
msgid "INTERFACE_IS_NOT_USED_OR_FORM_UNIQUE_URL_NOT_SET"
msgstr ""
"L'utilisation de l'interface est désactivée dans le workflow ou l'URL "
"unique n'est pas configurée correctement"

