# French translations for Open-Capture
# Copyright (C) 2019 ORGANIZATION
# This file is distributed under the same license as the project
# FIRST AUTHOR <nathan.cheval@edissyum.com>, 2021.
msgid ""
msgstr ""
"Project-Id-Version:  0.1\n"
"Report-Msgid-Bugs-To: nathan.cheval@edissyum.com\n"
"POT-Creation-Date: 2023-03-29 14:52+0200\n"
"PO-Revision-Date: 2019-09-02 17:48+0200\n"
"Last-Translator: Nathan CHEVAL <nathan.cheval@edissyum.com>\n"
"Language: fr\n"
"Language-Team: fr <nathan.cheval@edissyum.com>\n"
"Plural-Forms: nplurals=2; plural=(n > 1);\n"
"MIME-Version: 1.0\n"
"Content-Type: text/plain; charset=utf-8\n"
"Content-Transfer-Encoding: 8bit\n"
"Generated-By: Babel 2.12.1\n"

#: launch_worker.py:48 launch_worker_splitter.py:48
msgid "FILE_UPLOADED"
msgstr "Fichier téléversé via fs-watcher avec la chaîne entrante"

#: src/backend/verifier_exports.py:86 src/backend/verifier_exports.py:89
msgid "XML_DESTINATION_FOLDER_DOESNT_EXISTS"
msgstr "Le dossier de destination XML n'existe pas"

#: src/backend/verifier_exports.py:264 src/backend/verifier_exports.py:267
#: src/backend/verifier_exports.py:333 src/backend/verifier_exports.py:336
msgid "PDF_DESTINATION_FOLDER_DOESNT_EXISTS"
msgstr "Le dossier de destination PDF n'existe pas"

#: src/backend/controllers/splitter.py:438
#: src/backend/controllers/splitter.py:444 src/backend/verifier_exports.py:488
#: src/backend/verifier_exports.py:494 src/backend/verifier_exports.py:500
msgid "EXPORT_MEM_ERROR"
msgstr "Erreur lors de l'export vers MEM Courrier"

#: src/backend/verifier_exports.py:495
msgid "PDF_FILE_NOT_FOUND"
msgstr "Le fichier PDF est introuvable"

#: src/backend/verifier_exports.py:506
msgid "MEM_WS_INFO_WRONG"
msgstr "Les informations de connexion à MEM Courrier sont erronées"

#: src/backend/controllers/splitter.py:450 src/backend/verifier_exports.py:512
msgid "MEM_WS_INFO_EMPTY"
msgstr "Les informations de connexion à MEM Courrier sont vides"

#: src/backend/classes/MEMWebServices.py:39
msgid "HOST_NOT_FOUND"
msgstr "L'URL de l'hôte n'existe pas"

#: src/backend/classes/SMTP.py:218
msgid "RESET_PASSWORD"
msgstr "Réinitialiser le mot de passe"

#: src/backend/classes/SMTP.py:220
msgid "FORGOT_EMAIL_HEADER"
msgstr ""
"Bonjour,<br/><br/>Vous avez demandé à réinitialiser le mot de passe de "
"votre compte Open-Capture.<br/><br/>Pour modifier votre mot de passe, "
"veuillez cliquer sur le lien ci-dessous :<br/><br/>"

#: src/backend/classes/SMTP.py:220
msgid "CLICK_HERE"
msgstr "Cliquez ici"

#: src/backend/classes/SMTP.py:220
msgid "FORGOT_EMAIL_FOOTER"
msgstr ""
"<br/><br/>Si vous n'êtes pas à l'origine de cette demande, merci "
"d'ignorer cet e-mail."

#: src/backend/controllers/accounts.py:45 src/backend/models/accounts.py:61
msgid "GET_SUPPLIER_BY_ID_ERROR"
msgstr "Erreur lors de la récupération du compte fournisseur"

#: src/backend/controllers/accounts.py:58 src/backend/models/accounts.py:84
msgid "GET_ADDRESS_BY_ID_ERROR"
msgstr "Erreur lors de la récupération de l'adresse"

#: src/backend/controllers/accounts.py:85
#: src/backend/controllers/accounts.py:174
msgid "UPDATE_SUPPLIER_POSITIONS_ERROR"
msgstr "Erreur lors de la mise à jour des positions du compte fournisseur"

#: src/backend/controllers/accounts.py:112
#: src/backend/controllers/accounts.py:205
msgid "UPDATE_SUPPLIER_PAGES_ERROR"
msgstr "Erreur lors de la mise à jour des pages du compte fournisseur"

#: src/backend/controllers/accounts.py:137
#: src/backend/controllers/accounts.py:143
msgid "UPDATE_SUPPLIER_ERROR"
msgstr "Erreur lors de la mise à jour du fournisseur"

#: src/backend/controllers/accounts.py:229
#: src/backend/controllers/accounts.py:235
#: src/backend/controllers/accounts.py:259
#: src/backend/controllers/accounts.py:265 src/backend/models/accounts.py:130
msgid "UPDATE_ADDRESS_ERROR"
msgstr "Erreur lors de la mise à jour de l'adresse"

#: src/backend/controllers/accounts.py:289 src/backend/models/accounts.py:150
msgid "CREATE_ADDRESS_ERROR"
msgstr "Erreur lors de la création de l'adresse"

#: src/backend/controllers/accounts.py:330
#: src/backend/controllers/accounts.py:336 src/backend/models/accounts.py:170
msgid "CREATE_SUPPLIER_ERROR"
msgstr "Erreur lors de la création du compte fournisseur"

#: src/backend/controllers/accounts.py:337
msgid "SUPPLIER_VAT_NUMBER_ALREADY_EXISTS"
msgstr "Un compte fournisseur existe déjà avec ce numéro de TVA"

#: src/backend/controllers/accounts.py:357 src/backend/controllers/user.py:215
#: src/backend/controllers/user.py:245 src/backend/models/accounts.py:234
#: src/backend/models/accounts.py:257 src/backend/models/accounts.py:276
#: src/backend/models/user.py:209
msgid "GET_CUSTOMER_BY_ID_ERROR"
msgstr "Erreur lors de la récupération du compte client"

#: src/backend/controllers/accounts.py:399
#: src/backend/controllers/accounts.py:405 src/backend/models/accounts.py:298
msgid "UPDATE_CUSTOMER_ERROR"
msgstr "Erreur lors de la mise à jour du compte client"

#: src/backend/controllers/accounts.py:434
#: src/backend/controllers/accounts.py:440 src/backend/models/accounts.py:318
msgid "CREATE_CUSTOMER_ERROR"
msgstr "Erreur lors de la création du compte client"

#: src/backend/controllers/accounts.py:441
msgid "CUSTOMER_VAT_NUMBER_ALREADY_EXISTS"
msgstr "Un compte client existe déjà avec ce numéro de TVA"

#: src/backend/controllers/accounts.py:455
#: src/backend/controllers/accounts.py:461 src/backend/models/accounts.py:340
msgid "DELETE_CUSTOMER_ERROR"
msgstr "Erreur lors de la suppression du compte client"

#: src/backend/controllers/accounts.py:476
#: src/backend/controllers/accounts.py:482 src/backend/models/accounts.py:192
msgid "DELETE_SUPPLIER_ERROR"
msgstr "Erreur lors de la suppression du compte fournisseur"

#: src/backend/controllers/accounts.py:504
msgid "LOAD_SUPPLIER_REFERENCIAL_ERROR"
msgstr "Erreur lors du chargement du référentiel fournisseur"

#: src/backend/controllers/artificial_intelligence.py:79
#: src/backend/controllers/artificial_intelligence.py:392
msgid "GET_IA_MODEL_BY_ID_ERROR"
msgstr "Erreur lors de la récupération du modèle d'apprentissage"

#: src/backend/controllers/artificial_intelligence.py:103
msgid "CREATE_IA_MODEL_ERROR"
msgstr "Erreur lors de la création du modèle d'apprentissage"

#: src/backend/controllers/artificial_intelligence.py:114
msgid "UPDATE_IA_MODEL_ERROR"
msgstr "Erreur lors de la mise à jour du modèle d'apprentissage"

#: src/backend/controllers/artificial_intelligence.py:393
#: src/backend/models/artificial_intelligence.py:59
msgid "IA_MODEL_DOESNT_EXISTS"
msgstr "Le modèle d'apprentissage n'existe pas"

#: src/backend/controllers/auth.py:65 src/backend/controllers/auth.py:215
#: src/backend/controllers/auth.py:254 src/backend/controllers/auth.py:262
#: src/backend/controllers/auth.py:265 src/backend/controllers/auth.py:267
msgid "JWT_ERROR"
msgstr "Erreur lors de l'authentification par token"

#: src/backend/controllers/auth.py:114
msgid "RESET_JWT_ERROR"
msgstr "Erreur lors de l'utilisation du token de réinitialisation"

#: src/backend/controllers/auth.py:147 src/backend/controllers/auth.py:194
#: src/backend/controllers/auth.py:239 src/backend/controllers/auth.py:286
#: src/backend/controllers/auth.py:297 src/backend/controllers/auth.py:307
#: src/backend/controllers/auth.py:334 src/backend/rest/auth.py:69
msgid "LOGIN_ERROR"
msgstr "Erreur lors de la connexion"

#: src/backend/controllers/auth.py:262
msgid "ACCOUNT_ALREADY_LOGGED"
msgstr ""
"Votre compte est déjà connecté sur un autre poste. Une seule connexion "
"est autorisée par utilisateur"

#: src/backend/controllers/auth.py:298
msgid "SEVERAL_AUTH_METHODS_ENABLED"
msgstr "Plusieurs méthodes d'authentification sont activées"

#: src/backend/controllers/auth.py:322
msgid "LDAP_ERROR"
msgstr "Erreur LDAP"

#: src/backend/controllers/auth.py:323 src/backend/models/auth.py:140
msgid "NO_LDAP_CONFIGURATIONS_FOUND"
msgstr "Aucune configurations LDAP n'est disponible"

#: src/backend/controllers/auth.py:349
msgid "LOADING_METHODS_AUTH_ERROR"
msgstr "Echec lors de l'exécution de la requête"

#: src/backend/controllers/auth.py:361
msgid "DISABLE_LOGIN_METHOD_ERROR"
msgstr "Erreur lors de la désactivation de cette méthode"

#: src/backend/controllers/auth.py:373
msgid "ENABLE_LOGIN_METHOD_ERROR"
msgstr "Erreur lors de l'activation de cette méthode"

#: src/backend/controllers/auth.py:396 src/backend/controllers/auth.py:581
#: src/backend/controllers/auth.py:637 src/backend/controllers/auth.py:652
#: src/backend/controllers/auth.py:660 src/backend/controllers/auth.py:666
msgid "LDAP_CONNECTION_ERROR"
msgstr "Impossible de se connecter au serveur LDAP"

#: src/backend/controllers/auth.py:397
msgid "LOGIN_LDAP_ERROR"
msgstr "Information(s) de connexion incorrecte(s)"

#: src/backend/controllers/auth.py:569 src/backend/controllers/auth.py:575
msgid "LDAP_SYNCHRO_INFOS_ERROR"
msgstr "Information(s) de synchronisation incorrecte(s)"

#: src/backend/controllers/auth.py:571 src/backend/controllers/auth.py:577
#: src/backend/controllers/auth.py:583 src/backend/controllers/auth.py:589
#: src/backend/controllers/auth.py:595
msgid "LDAP_SYNCHRO_ERROR"
msgstr "Erreur lors de la synchronisation LDAP"

#: src/backend/controllers/auth.py:587 src/backend/controllers/auth.py:593
#: src/backend/controllers/auth.py:672 src/backend/rest/auth.py:117
msgid "INFOS_LDAP_NOT_COMPLETE"
msgstr "Informations non complètes"

#: src/backend/controllers/auth.py:635 src/backend/controllers/auth.py:650
#: src/backend/controllers/auth.py:658
msgid "BAD_CONNECTION_LDAP_INFOS"
msgstr "Information(s) incorrecte(s)"

#: src/backend/controllers/auth.py:670 src/backend/rest/auth.py:115
msgid "NOT_COMPLETE_CONNECTION_INFOS"
msgstr "Il manque une ou plusieurs informations pour établir la connexion"

#: src/backend/controllers/config.py:61
msgid "RETRIEVE_CONFIGURATION_ERRORS"
msgstr "Erreur lors de la récupération de la configuration"

#: src/backend/controllers/config.py:77
msgid "RETRIEVE_CONFIGURATIONS_ERRORS"
msgstr "Erreur lors de la récupération des configurations"

#: src/backend/controllers/config.py:93
msgid "RETRIEVE_DOCSERVERS_ERRORS"
msgstr "Erreur lors de la récupération des docservers"

#: src/backend/controllers/config.py:109
msgid "RETRIEVE_REGEX_ERRORS"
msgstr "Erreur lors de la récupération des regex"

#: src/backend/controllers/config.py:121 src/backend/controllers/config.py:141
#: src/backend/controllers/config.py:153 src/backend/controllers/config.py:173
#: src/backend/models/config.py:199 src/backend/models/config.py:223
msgid "UPDATE_CONFIGURATION_ERROR"
msgstr "Erreur lors de la mise à jour de la configuration"

#: src/backend/controllers/config.py:122 src/backend/controllers/config.py:154
msgid "JWT_EXPIRATION_COULDNT_BE_ZERO_OR_LESS"
msgstr "La valeur d'expiration du token ne peut être inférieure à 0"

#: src/backend/controllers/config.py:194 src/backend/models/config.py:245
msgid "UPDATE_REGEX_ERROR"
msgstr "Erreur lors de la mise à jour des REGEX"

#: src/backend/controllers/config.py:214 src/backend/models/config.py:271
msgid "UPDATE_DOCSERVER_ERROR"
msgstr "Erreur lors de la mise à jour de la docserver"

#: src/backend/controllers/config.py:255 src/backend/controllers/config.py:265
#: src/backend/controllers/config.py:270
msgid "ERROR_UPDATING_IMAGE"
msgstr "Erreur lors de la modification de l'image de connexion"

#: src/backend/controllers/config.py:256 src/backend/controllers/config.py:266
msgid "CUSTOM_IMAGE_PATH_NOT_WRITEABLE_OR_NOT_EXISTS"
msgstr "Le dossier d'image du custom n'est pas accessible"

#: src/backend/controllers/config.py:271
msgid "CUSTOM_NOT_PRESENT"
msgstr "Aucun custom n'est présent"

#: src/backend/controllers/custom_fields.py:33
#: src/backend/controllers/custom_fields.py:49
#: src/backend/controllers/custom_fields.py:62
msgid "CUSTOM_FIELDS_ERROR"
msgstr "Erreur sur les champs personnalisés"

#: src/backend/controllers/custom_fields.py:75
msgid "CUSTOM_FIELDS_DELETE_ERROR"
msgstr "Erreur lors de la suppression du champ personnalisé"

#: src/backend/controllers/doctypes.py:34
#: src/backend/controllers/doctypes.py:76 src/backend/models/doctypes.py:131
#: src/backend/models/doctypes.py:134
msgid "SET_DEFAULT_DOCTYPE_ERROR"
msgstr "Erreur lors de la modification du type de document par défaut"

#: src/backend/controllers/doctypes.py:40 src/backend/models/doctypes.py:51
msgid "ADD_DOCTYPE_ERROR"
msgstr "Erreur lors de l'ajout d'un type de document"

#: src/backend/controllers/doctypes.py:60
#: src/backend/controllers/doctypes.py:96
#: src/backend/controllers/doctypes.py:109
#: src/backend/controllers/doctypes.py:161
#: src/backend/controllers/doctypes.py:192
msgid "DOCTYPE_ERROR"
msgstr "Erreur sur les types de documents"

#: src/backend/controllers/doctypes.py:128
msgid "BUNDLESEPARATOR"
msgstr "SEPARATEUR DE LOT / BUNDLE SEPARATOR"

#: src/backend/controllers/doctypes.py:135
msgid "DOCUMENTSEPARATOR"
msgstr "SEPARATEUR DE DOCUMENT / DOCUMENT SEPARATOR"

#: src/backend/controllers/doctypes.py:154
msgid "DOCTYPESEPARATOR"
msgstr "SEPARATEUR AVEC TYPE DE DOCUMENT / SEPARATOR WITH DOCUMENT TYPE"

#: src/backend/controllers/forms.py:71 src/backend/controllers/forms.py:97
#: src/backend/controllers/forms.py:214
msgid "FORMS_ERROR"
msgstr "Erreur sur les formulaires"

#: src/backend/controllers/forms.py:112 src/backend/controllers/forms.py:161
#: src/backend/models/forms.py:66
msgid "GET_FORM_BY_ID_ERROR"
msgstr "Erreur lors de la récupération du formulaire"

#: src/backend/controllers/forms.py:144
msgid "GET_FORM_FIELDS_BY_FORM_ID_ERROR"
msgstr "Erreur lors de la récupération des champs du formulaire"

#: src/backend/controllers/forms.py:208 src/backend/controllers/forms.py:337
#: src/backend/controllers/forms.py:343
msgid "UPDATE_FORMS_FIELDS_ERROR"
msgstr "Erreur lors de la mise à jour des champs du formulaire"

#: src/backend/controllers/forms.py:228 src/backend/controllers/forms.py:234
msgid "DELETE_FORM_ERROR"
msgstr "Erreur lors de la suppression du formulaire"

#: src/backend/controllers/forms.py:243 src/backend/controllers/inputs.py:107
#: src/backend/controllers/outputs.py:58
#: src/backend/controllers/positions_masks.py:160
msgid "COPY_OF"
msgstr "Copie de"

#: src/backend/controllers/forms.py:261 src/backend/controllers/forms.py:267
msgid "DUPLICATE_FORM_ERROR"
msgstr "Erreur lors de la duplication du formulaire"

#: src/backend/controllers/forms.py:281 src/backend/controllers/forms.py:287
msgid "DISABLE_FORM_ERROR"
msgstr "Erreur lors de la désactivation du formulaire"

#: src/backend/controllers/forms.py:301 src/backend/controllers/forms.py:307
msgid "ENABLE_FORM_ERROR"
msgstr "Erreur lors de l'activation du formulaire"

#: src/backend/controllers/forms.py:323
msgid "GET_FORMS_FIELDS_ERROR"
msgstr "Erreur lors de la récupération des champs du formulaire"

#: src/backend/controllers/history.py:28
msgid "ADD_HISTORY_ERROR"
msgstr "Erreur lors de l'ajout dans l'historique"

#: src/backend/controllers/inputs.py:75 src/backend/controllers/inputs.py:135
#: src/backend/controllers/inputs.py:162 src/backend/controllers/inputs.py:173
#: src/backend/controllers/inputs.py:186
msgid "CREATE_INPUT_ERROR"
msgstr "Erreur lors de la création de la chaîne entrante"

#: src/backend/controllers/inputs.py:76 src/backend/controllers/inputs.py:136
msgid "NOT_ALLOWED_INPUT_PATH"
msgstr "Le chemin de capture de la chaîne entrante n'est pas autorisé"

#: src/backend/controllers/inputs.py:89 src/backend/controllers/inputs.py:95
msgid "UPDATE_INPUT_ERROR"
msgstr "Erreur lors de la mise à jour de la chaîne entrante"

#: src/backend/controllers/inputs.py:120 src/backend/controllers/inputs.py:126
msgid "DUPLICATE_INPUT_ERROR"
msgstr "Erreur lors de la duplication de la chaîne entrante"

#: src/backend/controllers/inputs.py:163
msgid "INPUT_ID_ALREADY_EXISTS"
msgstr "Le libellé technique de la chaîne entrante existe déjà"

#: src/backend/controllers/inputs.py:174
msgid "INPUT_FOLDER_ALREADY_EXISTS"
msgstr "Le chemin de capture est déjà paramétré dans une autre chaîne entrante"

#: src/backend/controllers/inputs.py:199
msgid "GET_INPUT_BY_ID_ERROR"
msgstr "Erreur lors de récupération de la chaîne entrante"

#: src/backend/controllers/inputs.py:212
msgid "GET_INPUT_BY_INPUT_ID_ERROR"
msgstr "Erreur lors de la récupération de la chaîne entrante"

#: src/backend/controllers/inputs.py:233 src/backend/controllers/inputs.py:239
msgid "DELETE_INPUT_ERROR"
msgstr "Erreur lors de le suppression de la chaîne entrante"

#: src/backend/controllers/inputs.py:275
msgid "FS_WATCHER_DELETION_ERROR"
msgstr "Erreur lors de la suppression des paramètres du fs watcher"

#: src/backend/controllers/inputs.py:276 src/backend/controllers/inputs.py:343
msgid "FS_WATCHER_CONFIG_DOESNT_EXIST"
msgstr "La configuration du fs watcher est introuvable"

#: src/backend/controllers/inputs.py:322 src/backend/controllers/inputs.py:342
msgid "FS_WATCHER_CREATION_ERROR"
msgstr "Erreur lors de la création des paramètres du fs watcher"

#: src/backend/controllers/inputs.py:323
msgid "CAN_NOT_CREATE_FOLDER_PERMISSION_ERROR"
msgstr "Problème de permissions pour créer le dossier"

#: src/backend/controllers/inputs.py:348
msgid "SCRIPT_SAMPLE_DOESNT_EXISTS"
msgstr "Le script d'exemple n'existe pas"

#: src/backend/controllers/inputs.py:354
msgid "SCRIPT_FOLDER_DOESNT_EXISTS"
msgstr "Le dossier des scripts n'existe pas"

#: src/backend/controllers/mailcollect.py:36
msgid "RETRIEVE_PROCESSES_ERROR"
msgstr "Erreur lors de la récupération des processus MailCollect"

#: src/backend/controllers/mailcollect.py:52
msgid "UPDATE_PROCESS_ERROR"
msgstr "Erreur lors de la mise à jour du processus MailCollect"

#: src/backend/controllers/mailcollect.py:68
msgid "CREATE_PROCESS_ERROR"
msgstr "Erreur lors de la création d'un processus MailCollect"

#: src/backend/controllers/mailcollect.py:82
#: src/backend/controllers/mailcollect.py:88
msgid "DELETE_MAILCOLLECT_PROCESS_ERROR"
msgstr "Erreur lors de la suppression d'un processus MailCollect"

#: src/backend/controllers/mailcollect.py:102
#: src/backend/controllers/mailcollect.py:108
msgid "ENABLE_MAILCOLLECT_PROCESS_ERROR"
msgstr "Erreur lors de l'activation d'un processus MailCollect"

#: src/backend/controllers/mailcollect.py:122
#: src/backend/controllers/mailcollect.py:128
msgid "DISABLE_MAILCOLLECT_PROCESS_ERROR"
msgstr "Erreur lors de la désactivation d'un processus MailCollect"

#: src/backend/controllers/mailcollect.py:142
#: src/backend/controllers/mailcollect.py:152
msgid "MAILCOLLECT_ERROR"
msgstr "Erreur MailCollect"

#: src/backend/controllers/outputs.py:65 src/backend/controllers/outputs.py:71
msgid "DUPLICATE_OUTPUT_ERROR"
msgstr "Erreur lors de la duplication de la chaîne sortante"

#: src/backend/controllers/outputs.py:100
#: src/backend/controllers/outputs.py:122
#: src/backend/controllers/outputs.py:128
msgid "UPDATE_OUTPUT_ERROR"
msgstr "Erreur lors de mise à jour de la chaîne sortante"

#: src/backend/controllers/outputs.py:101
msgid "NOT_ALLOWED_OUTPUT_PATH"
msgstr "Le chemin d'export de la chaîne sortant n'est pas autorisé"

#: src/backend/controllers/outputs.py:152
msgid "CREATE_OUTPUT_ERROR"
msgstr "Erreur lors de la création de la chaîne sortante"

#: src/backend/controllers/outputs.py:165
msgid "GET_OUTPUT_BY_ID_ERROR"
msgstr "Erreur lors de la récupération de la chaîne sortante"

#: src/backend/controllers/outputs.py:178
msgid "GET_OUTPUT_TYPE_BY_ID_ERROR"
msgstr "Erreur lors de la récupération des types de chaîne sortante"

#: src/backend/controllers/outputs.py:192
#: src/backend/controllers/outputs.py:198
msgid "DELETE_OUTPUT_ERROR"
msgstr "Erreur lors de la suppression de la chaîne sortante"

#: src/backend/controllers/positions_masks.py:42
#: src/backend/controllers/positions_masks.py:66
#: src/backend/controllers/positions_masks.py:125
#: src/backend/controllers/positions_masks.py:131
msgid "POSITION_MASKS_ERROR"
msgstr "Erreur sur les masques de positionnement"

#: src/backend/controllers/positions_masks.py:81
#: src/backend/controllers/positions_masks.py:98
msgid "GET_POSITION_MASK_BY_ID_ERROR"
msgstr "Erreur lors de la récupération du masque de positionnement"

#: src/backend/controllers/positions_masks.py:145
#: src/backend/controllers/positions_masks.py:151
msgid "DELETE_POSITION_MASK_ERROR"
msgstr "Erreur lors de la suppression du masque de positionnement"

#: src/backend/controllers/positions_masks.py:176
#: src/backend/controllers/positions_masks.py:182
msgid "DUPLICATE_POSITIONS_MASKS_ERROR"
msgstr "Erreur lors de la duplication du masque de positionnement"

#: src/backend/controllers/positions_masks.py:196
#: src/backend/controllers/positions_masks.py:202
msgid "DISABLE_POSITION_MASK_ERROR"
msgstr "Erreur lors de désactivation du masque de positionnement"

#: src/backend/controllers/positions_masks.py:216
#: src/backend/controllers/positions_masks.py:222
msgid "ENABLE_POSITION_MASK_ERROR"
msgstr "Erreur lors de l'activation du masque de positionnement"

#: src/backend/controllers/positions_masks.py:245
msgid "UPDATE_POSITIONS_BY_POSITIONS_MASK_ID_ERROR"
msgstr "Erreur lors de la mise à jour des positions du masque de positionnement"

#: src/backend/controllers/positions_masks.py:268
msgid "UPDATE_PAGES_BY_POSITIONS_MASK_ID_ERROR"
msgstr "Erreur lors de la mise à jour des pages du masque de positionnement"

#: src/backend/controllers/positions_masks.py:286
msgid "DELETE_POSITIONS_BY_POSITION_MASK_ID_ERROR"
msgstr "Erreur lors de la suppression des positions du masque de positionnement"

#: src/backend/controllers/positions_masks.py:304
msgid "DELETE_PAGES_BY_POSITION_MASK_ID_ERROR"
msgstr "Erreur lors de la suppression des pages du masque de positionnement"

#: src/backend/controllers/privileges.py:37
#: src/backend/controllers/privileges.py:65
msgid "GET_PRIVILEGES_ERROR"
msgstr "Erreur lors de la récupération des privilèges"

#: src/backend/controllers/roles.py:47 src/backend/controllers/roles.py:53
#: src/backend/controllers/roles.py:95 src/backend/controllers/roles.py:101
#: src/backend/models/roles.py:84
msgid "UPDATE_ROLE_ERROR"
msgstr "Erreur lors de la mise à jour du rôle"

#: src/backend/controllers/roles.py:75 src/backend/models/roles.py:104
msgid "CREATE_ROLE_ERROR"
msgstr "Erreur lors de la création du rôle"

#: src/backend/controllers/roles.py:114
msgid "GET_ROLE_BY_ID_ERROR"
msgstr "Erreur lors de la récupération du rôle"

#: src/backend/controllers/roles.py:128 src/backend/controllers/roles.py:134
msgid "DELETE_ROLE_ERROR"
msgstr "Erreur lors de la suppression du rôle"

#: src/backend/controllers/roles.py:148 src/backend/controllers/roles.py:154
msgid "DISABLE_ROLE_ERROR"
msgstr "Erreur lors de la désactivation du rôle"

#: src/backend/controllers/roles.py:168 src/backend/controllers/roles.py:174
msgid "ENABLE_ROLE_ERROR"
msgstr "Erreur lors de l'activation du rôle"

#: src/backend/controllers/splitter.py:91
msgid "LOAD_METADATA_ERROR"
msgstr "Erreur du chargement des métadonnées"

#: src/backend/controllers/splitter.py:137
#: src/backend/controllers/verifier.py:75
msgid "AT"
msgstr "à"

#: src/backend/controllers/splitter.py:161
msgid "FORM_UNDEFINED"
msgstr "Formulaire non défini"

#: src/backend/controllers/splitter.py:164
msgid "CUSTOMER_UNDEFINED"
msgstr "Compte client non défini"

#: src/backend/controllers/splitter.py:232
msgid "BATCH_NOT_FOUND"
msgstr "Lot non trouvé"

#: src/backend/controllers/splitter.py:233
msgid "BATCH_ID_NOT_FOUND"
msgstr "Lot  %(id)s non trouvé"

#: src/backend/controllers/splitter.py:242
#: src/backend/controllers/verifier.py:616
msgid "UPDATE_STATUS_ERROR"
msgstr "Erreur lors de la mise à jour du statut"

#: src/backend/controllers/splitter.py:277
#: src/backend/controllers/verifier.py:348
msgid "REMOVE_LOCK_BY_USER_ID_ERROR"
msgstr "Erreur lors de la suppression du verrou"

#: src/backend/controllers/splitter.py:387
msgid "ADD_DOCUMENT_ERROR"
msgstr "Erreur lors de l'ajout d'un document"

#: src/backend/controllers/splitter.py:522
#: src/backend/controllers/splitter.py:784
msgid "EXPORT_PDF_ERROR"
msgstr "Erreur lors de l'export PDF"

#: src/backend/controllers/splitter.py:544
#: src/backend/controllers/splitter.py:809
msgid "EXPORT_XML_ERROR"
msgstr "Erreur lors de l'export XML"

#: src/backend/controllers/splitter.py:560
msgid "UPDATE_BATCH_ERROR"
msgstr "Erreur lors de la mise à jour du lot"

#: src/backend/controllers/splitter.py:573
msgid "UPDATE_DOCUMENTS_ERROR"
msgstr "Erreur lors de la mise à jour du document"

#: src/backend/controllers/splitter.py:586
msgid "UPDATE_DOCUMENT_ERROR"
msgstr "Erreur lors de la mise à jour du document"

#: src/backend/controllers/splitter.py:601
#: src/backend/controllers/splitter.py:622
#: src/backend/controllers/splitter.py:637
#: src/backend/controllers/splitter.py:652
msgid "UPDATE_PAGES_ERROR"
msgstr "Erreur lors de la modification des pages"

#: src/backend/controllers/splitter.py:666
msgid "CMIS_CONNECTION_ERROR"
msgstr "Erreur lors de la connexion CMIS"

#: src/backend/controllers/splitter.py:679
msgid "OPENADS_CONNECTION_ERROR"
msgstr "Erreur lors de la connexion OpenADS"

#: src/backend/controllers/splitter.py:859
msgid "CHECK_FOLDER_ERROR"
msgstr "Erreur lors de la vérification du dossier"

#: src/backend/controllers/splitter.py:860
msgid "FOLDER_DOES_NOT_EXIST"
msgstr "Dossier inexistant"

#: src/backend/controllers/splitter.py:877
msgid "OPENADS_ADD_DOC_ERROR"
msgstr "Erreur lors de l'envoi de document à OpenADS"

#: src/backend/controllers/splitter.py:971
#: src/backend/controllers/verifier.py:595 src/backend/models/splitter.py:572
#: src/backend/models/verifier.py:171
msgid "GET_TOTALS_ERROR"
msgstr "Erreur lors de la récupération des totaux"

#: src/backend/controllers/status.py:31
msgid "RETRIEVES_STATUS_ERROR"
msgstr "Erreur lors de la récupération des status"

#: src/backend/controllers/tasks_watcher.py:34
msgid "CREATE_TASK_ERROR"
msgstr "Erreur lors de la création d'une nouvelle tâche"

#: src/backend/controllers/user.py:64
msgid "CREATE_USER_ERROR"
msgstr "Erreur lors de la création de l'utilisateur"

#: src/backend/controllers/user.py:103 src/backend/controllers/user.py:120
#: src/backend/controllers/user.py:186 src/backend/models/user.py:139
#: src/backend/models/user.py:186
msgid "GET_USER_BY_ID_ERROR"
msgstr "Erreur lors de la récupération de l'utilisateur"

#: src/backend/controllers/user.py:137
msgid "GET_USER_BY_USERNAME_ERROR"
msgstr "Erreur lors de la récupération de l'utilisateur"

#: src/backend/controllers/user.py:160
msgid "SEND_EMAIL_FORGOT_PASSWORD_ERROR"
msgstr "Erreur lors de l'envoi de l'email de réinitialisation du mot de passe"

#: src/backend/controllers/user.py:180 src/backend/controllers/user.py:185
msgid "RESET_PASSWORD_ERROR"
msgstr "Erreur lors de la réinitilisation du mot de passe"

#: src/backend/controllers/user.py:181
msgid "RESET_TOKEN_MISMATCH"
msgstr "Le token de réinitialisation est invalide. Il est peut être expiré"

#: src/backend/controllers/user.py:266
msgid "UPDATE_PROFILE"
msgstr "Mise à jour du profile"

#: src/backend/controllers/user.py:267
msgid "ERROR_OLD_PASSWORD_NOT_MATCH"
msgstr "L'ancien mot de passe ne corresponds pas"

#: src/backend/controllers/user.py:273
msgid "UPDATE_USER"
msgstr "Mise à jour de l'utilisateur"

#: src/backend/controllers/user.py:274
msgid "ERROR_PASSWORD_NOT_MATCH"
msgstr "Les mots de passes ne correspondent pas"

#: src/backend/controllers/user.py:301 src/backend/controllers/user.py:307
#: src/backend/models/user.py:254 src/backend/models/user.py:320
msgid "UPDATE_USER_ERROR"
msgstr "Erreur lors de la mise à jour de l'utilisateur"

#: src/backend/controllers/user.py:321 src/backend/controllers/user.py:327
msgid "DELETE_USER_ERROR"
msgstr "Erreur lors de la suppression de l'utilisateur"

#: src/backend/controllers/user.py:341 src/backend/controllers/user.py:347
msgid "DISABLE_USER_ERROR"
msgstr "Erreur lors de désactiver de l'utilisateur"

#: src/backend/controllers/user.py:361 src/backend/controllers/user.py:367
msgid "ENABLE_USER_ERROR"
msgstr "Erreur lors de l'activation de l'utilisateur"

#: src/backend/controllers/user.py:384 src/backend/controllers/user.py:390
#: src/backend/models/user.py:276
msgid "UPDATE_CUSTOMERS_USER_ERROR"
msgstr "Erreur lors de la mise à jour des comptes clients de l'utilisateur"

#: src/backend/controllers/user.py:405 src/backend/controllers/user.py:412
#: src/backend/models/user.py:298
msgid "UPDATE_FORMS_USER_ERROR"
msgstr "Erreur lors de la mise à jour des formulaires de l'utilisateur"

#: src/backend/controllers/verifier.py:56 src/backend/models/splitter.py:219
#: src/backend/models/verifier.py:40
msgid "GET_INVOICE_BY_ID_ERROR"
msgstr "Erreur lors de la récupération de la facture"

#: src/backend/controllers/verifier.py:170
#: src/backend/controllers/verifier.py:272
msgid "UPDATE_INVOICE_POSITIONS_ERROR"
msgstr "Erreur lors de la mise à jour des positions de la facture"

#: src/backend/controllers/verifier.py:193
#: src/backend/controllers/verifier.py:290
msgid "UPDATE_INVOICE_PAGES_ERROR"
msgstr "Erreur lors de la mise à jour des pages de la facture"

#: src/backend/controllers/verifier.py:216
#: src/backend/controllers/verifier.py:234
msgid "UPDATE_INVOICE_DATA_ERROR"
msgstr "Erreur lors de la mise à jour des données de la facture"

#: src/backend/controllers/verifier.py:304
#: src/backend/controllers/verifier.py:310
msgid "DELETE_INVOICE_ERROR"
msgstr "Erreur lors de la suppression de la facture"

#: src/backend/controllers/verifier.py:325
#: src/backend/controllers/verifier.py:331
msgid "UPDATE_INVOICE_ERROR"
msgstr "Erreur lors de la mise à jour de la facture"

#: src/backend/controllers/verifier.py:495
#: src/backend/controllers/verifier.py:498
#: src/backend/controllers/verifier.py:515
#: src/backend/controllers/verifier.py:538
#: src/backend/controllers/verifier.py:539
msgid "API_INSEE_ERROR_CONNEXION"
msgstr "Erreur lors de la connexion à l'api de l'INSEE"

#: src/backend/controllers/verifier.py:567
msgid "VAT_NOT_VALID"
msgstr "Numéro de TVA invalide"

#: src/backend/controllers/verifier.py:572
#: src/backend/controllers/verifier.py:573
msgid "VAT_API_ERROR"
msgstr "Impossible de joindre l'API de vérification du numéro de TVA"

#: src/backend/controllers/verifier.py:607
msgid "INVOICE_NOT_FOUND"
msgstr "Facture non trouvée"

#: src/backend/controllers/verifier.py:608
msgid "INVOICE_ID_NOT_FOUND"
msgstr "Facture  %(id)s non trouvée"

#: src/backend/models/accounts.py:108
msgid "SUPPLIER_UPDATE_ERROR"
msgstr "Erreur lors de la mise à jour du fournisseur"

#: src/backend/models/artificial_intelligence.py:80
msgid "IA_MODEL_CREATE_ERROR"
msgstr "Erreur lors de la création du modèle d'apprentissage"

#: src/backend/models/artificial_intelligence.py:101
msgid "IA_MODEL_UPDATE_ERROR"
msgstr "Erreur lors de la modification du modèle d'apprentissage"

#: src/backend/models/auth.py:43 src/backend/models/auth.py:101
#: src/backend/models/user.py:43 src/backend/rest/auth.py:70
msgid "BAD_USERNAME"
msgstr "Mauvais nom de compte"

#: src/backend/models/auth.py:45 src/backend/models/user.py:45
msgid "BAD_PASSWORD"
msgstr "Mauvais mot de passe"

#: src/backend/models/auth.py:47
msgid "USER_DELETED"
msgstr "Utilisateur supprimé"

#: src/backend/models/auth.py:49
msgid "USER_DISABLED"
msgstr "Utilisateur desactivé"

#: src/backend/models/auth.py:70 src/backend/models/auth.py:80
#: src/backend/models/roles.py:60
msgid "ROLE_DOESNT_EXISTS"
msgstr "Le rôle n'existe pas"

#: src/backend/models/auth.py:165
msgid "UPDATE_LOGIN_METHOD_ERROR"
msgstr "Erreur lors de la mise à jour de la méthode d'authentification"

#: src/backend/models/auth.py:211
msgid "DISABLE_LOGIN_METHOD_DATA_ERROR"
msgstr "Erreur lors de la désactivation de cette méthode d'authentification"

#: src/backend/models/auth.py:233
msgid "ENABLE_LOGIN_METHOD_DATA_ERROR"
msgstr "Erreur lors de l'activation de cette méthode d'authentification"

#: src/backend/models/custom_fields.py:55
msgid "ADD_CUSTOM_FIELD_ERROR"
msgstr "Erreur lors de la création du champ custom"

#: src/backend/models/custom_fields.py:58
msgid "CUSTOM_FIELD_ALREADY_EXIST"
msgstr "Le champ custom existe déjà"

#: src/backend/models/custom_fields.py:106
msgid "UPDATE_CUSTOM_FIELDS_ERROR"
msgstr "Erreur lors de la mise à jour du champ custom"

#: src/backend/models/custom_fields.py:129
msgid "DELETE_CUSTOM_FIELDS_ERROR"
msgstr "Erreur lors de la suppression du champ custom"

#: src/backend/models/doctypes.py:54
msgid "DOCTYPE_ALREADY_EXIST"
msgstr "Le type de document existe déjà"

#: src/backend/models/doctypes.py:100
msgid "UPDATE_DOCTYPE_ERROR"
msgstr "Erreur lors de la mise à jour du type de document"

#: src/backend/models/forms.py:45
#, fuzzy
msgid "GET_FORMS_ERROR"
msgstr "Erreur sur les formulaires"

#: src/backend/models/forms.py:89
msgid "GET_FORM_SETTINGS_BY_ID_ERROR"
msgstr "Erreur lors de la récupération des paramètres du formulaire"

#: src/backend/models/forms.py:112
msgid "GET_DEFAULT_FORM_ERROR"
msgstr "Erreur lors de la récupération du formulaire par défaut"

#: src/backend/models/forms.py:136
msgid "UPDATE_FORM_ERROR"
msgstr "Erreur lors de la mise à jour du formulaire"

#: src/backend/models/forms.py:158
msgid "UPDATE_FORM_FIELDS_ERROR"
msgstr "Erreur lors de la mise à jour des champs du formulaire"

#: src/backend/models/forms.py:215
msgid "ADD_FORM_ERROR"
msgstr "Erreur lors de la création du formulaire"

#: src/backend/models/forms.py:218
msgid "FORM_LABEL_ALREADY_EXIST"
msgstr "Le libellé de formulaire existe déjà"

#: src/backend/models/inputs.py:60 src/backend/models/inputs.py:83
msgid "INPUT_DOESNT_EXISTS"
msgstr "La chaîne entrante n'existe pas"

#: src/backend/models/inputs.py:125
msgid "INPUT_UPDATE_ERROR"
msgstr "Erreur lors de la mise à jour de la chaîne entrante"

#: src/backend/models/inputs.py:145
msgid "INPUT_CREATE_ERROR"
msgstr "Erreur lors de la création de la chaîne entrante"

#: src/backend/models/mailcollect.py:85
msgid "MAILCOLLECT_PROCESS_UPDATE_ERROR"
msgstr "Erreur lors de la mise à jour d'un processus MailCollect"

#: src/backend/models/outputs.py:78
msgid "OUTPUT_DOESNT_EXISTS"
msgstr "La chaîne sortante n'existe pas"

#: src/backend/models/outputs.py:101
msgid "OUTPUT_TYPE_DOESNT_EXISTS"
msgstr "Le type de chaîne sortante n'existe aps"

#: src/backend/models/outputs.py:125
msgid "OUTPUT_UPDATE_ERROR"
msgstr "Erreur lors de la mise à jour de la chaîne sortante"

#: src/backend/models/outputs.py:145
msgid "OUTPUT_CREATE_ERROR"
msgstr "Erreur lors de la création de la chaîne sortante"

#: src/backend/models/positions_masks.py:63
msgid "GET_POSITIONS_MASKS_BY_ID_ERROR"
msgstr "Erreur lors de la récupération du masque de positionnement"

#: src/backend/models/positions_masks.py:87
msgid "UPDATE_POSITIONS_MASKS_ERROR"
msgstr "Erreur lors de la mise à jour du masque de positionnement"

#: src/backend/models/positions_masks.py:109
msgid "UPDATE_POSITIONS_MASKS_FIELDS_ERROR"
msgstr "Erreur lors de la mise à jour des champs du masque de positionnement"

#: src/backend/models/positions_masks.py:144
msgid "ADD_POSITIONS_MASKS_ERROR"
msgstr "Erreur lors de la création du masque de positionnement"

#: src/backend/models/positions_masks.py:147
msgid "POSITIONS_MASK_LABEL_ALREADY_EXIST"
msgstr "Le libellé du masque de positionnement existe déjà"

#: src/backend/models/privileges.py:38 src/backend/models/privileges.py:59
msgid "ERROR_RETRIEVING_PRIVILEGES"
msgstr "Erreur lors de la récupération des privilèges"

#: src/backend/models/roles.py:126
msgid "ROLE_PRIVILEGES_UPDATE_ERROR"
msgstr "Erreur lors de la mise à jour des privilèges du rôle"

#: src/backend/models/roles.py:148
msgid "ROLE_PRIVILEGES_CREATE_ERROR"
msgstr "Erreur lors de la création des privilèges du rôle"

#: src/backend/models/splitter.py:78
msgid "GET_MAX_SPLIT_INDEX_ERROR"
msgstr "Erreur lors de l'obtention de l'index du Splitter"

#: src/backend/models/splitter.py:125
msgid "UPDATE_SETTINGS_ERROR"
msgstr "Erreur lors de la mise à jour des paramètres du Splitter"

#: src/backend/models/splitter.py:150
msgid "INSERT_PAGE_ERROR"
msgstr "Erreur lors de l'insertion des pages du Splitter"

#: src/backend/models/splitter.py:244
msgid "GET_DOCUMENTS_ERROR"
msgstr "Erreur lors de la récupération des documents du Splitter"

#: src/backend/models/splitter.py:266 src/backend/models/splitter.py:289
msgid "GET_PAGES_ERROR"
msgstr "Erreur lors de l'obtention des pages du Splitter"

#: src/backend/models/splitter.py:311
msgid "GET_MAX_SOURCE_PAGE_VALUE_ERROR"
msgstr "Erreur lors de l'obtention de la valeur des pages source du Splitter"

#: src/backend/models/splitter.py:334
msgid "GET_DOCUMENT_ERROR"
msgstr "Erreur lors de la récupération du document"

#: src/backend/models/splitter.py:356
msgid "GET_DOCUMENT_MAX_SPLIT_INDEX_ERROR"
msgstr "Erreur lors de l'obtention de l'index maximum du Splitter"

#: src/backend/models/status.py:40
msgid "NO_STATUS"
msgstr "Aucun status existant"

#: src/backend/models/tasks_watcher.py:89
msgid "UPDATE_TASK_ERROR"
msgstr "Erreur lors de la mise à jour d'une tâche"

#: src/backend/models/user.py:47
msgid "USER"
msgstr "L'utilisateur"

#: src/backend/models/user.py:47
msgid "ALREADY_REGISTERED"
msgstr "est déjà enregistré"

#: src/backend/models/user.py:162
msgid "GET_USER_BY_MAIL_ERROR"
msgstr "Aucun utilisateur asssocié à cette addresse email"

#: src/backend/models/user.py:231
#, fuzzy
msgid "GET_FORMS_BY_USER_ID_ERROR"
msgstr "Erreur lors de la récupération du formulaire"

#: src/backend/models/verifier.py:104 src/backend/models/verifier.py:125
msgid "INVOICE_UPDATE_ERROR"
msgstr "Erreur lors de la mise à jour de la facture"

#: src/backend/rest/auth.py:45 src/backend/rest/auth.py:74
msgid "PGSQL_ERROR"
msgstr "Erreur lors de la connexion à la base de donnée"

#: src/backend/rest/auth.py:140 src/backend/rest/auth.py:168
#: src/backend/rest/auth.py:183
msgid "REQUEST_MODIFS_ERROR"
msgstr "Erreur base de données impossible d'exécuter la requête"

#: src/backend/rest/auth.py:153
msgid "RETRIEVE_LOGIN_METHODS_ERROR"
msgstr "Erreur lors du chargement des méthodes d'authentification"

#: src/backend/rest/splitter.py:42 src/backend/rest/verifier.py:40
msgid "UNKNOW_ERROR"
msgstr "Erreur inconnue"

#~ msgid "GET_BATCH_ERROR"
#~ msgstr "Erreur lors de la récupération des lots du Splitter"

